Workbook

Sheet Instrucciones
A1: Base de usuarios del Rol de Instructores LP
A3: Usuarios | B3: Una fila por persona. Para agregar a alguien, escribe una fila nueva debajo de la última. Las celdas amarillas de la columna Correo corporativo están por completar.
A4: Rol | B4: Instructor o Administrador. Se elige de la lista.
A5: Activo | B5: SI o NO. Para dar de baja a alguien, cambia a NO en lugar de borrar la fila, así se conserva su historial.
A6: Registro | B6: Lo llena la aplicación en cada ingreso, salida o intento fallido. No hace falta editarla a mano.
A7: Ultimo_Acceso | B7: Se calcula sola desde Usuarios y Registro. No escribir aquí.
A8: Permisos | B8: Qué vistas ve cada rol. SI muestra la vista y NO la oculta.
A10: Ejemplo de fila en Usuarios | B10: BP 1234567 | Nombre Apellido | APELLIDO APELLIDO NOMBRE | nombre.apellido@latam.com | Instructor | A319/A320/A321/B767 | JSB | INS | SI
A11: Ejemplo de fila en Registro | B11: 27/09/2026 08:15:00 | 1234567 | Nombre Apellido | nombre.apellido@latam.com | Instructor | Ingreso | OK | Chrome en Windows
A12: Fuentes | B12: Un Google Sheet por mes (hoja ROL INS). Se agregan desde la app (Actualizar rol › Conectar Google Sheet) o escribiendo Mes (aaaa-mm) y el enlace. Activo = NO pausa la lectura.
A13: Solicitudes | B13: Pedidos de jefatura e instructores: BP, Nombre, Desde, Hasta, Tipo y Estado (asignado / no se asignó).
A14: Vigencias | B14: Experiencia reciente por BP (hoja BG INS). Escribe VENCIDO en la columna programada para generar una alerta.
A15: Acceso a la app | B15: Usuario = BP o correo corporativo. La primera vez, coordinación genera un código temporal (Usuarios y accesos) y la persona crea su contraseña. Las contraseñas no se guardan en este archivo.
... A18: SolicitudesVacaciones | B18: Lo llena la app cuando un instructor pide días. Coordinación aprueba o rechaza en la pestaña Vacaciones.

Sheet Vacaciones
A1: BP | B1: Nombre | C1: Fecha DGAC original | D1: Fecha DGAC 2025 | E1: Fecha DGAC 2026 | F1: Derecho 2025-26 | G1: Derecho 2026-27 | H1: Tomados 2025-26 | I1: Programado por mes 2026
A2: 29530 | B2: GUERRA SUAREZ JAZMIN | C2: 40567 | D2: 45681 | E2: 46046 | F2: 40 | G2: 41 | H2: 41 | I2: 5:8; 6:7; 10:15; 12:11
A3: 71348 | B3: MOZ MONTES KARLA LISSETTE | C3: 38223 | D3: 45893 | E3: 46258 | F3: 45 | G3: 45 | H3: 7 | I3: 2:7
A4: 967092 | B4: DAVILA BELLO MARIA ERIKA | C4: 38139 | D4: 45809 | E4: 46174 | F4: 45 | G4: 45 | H4: 46 | I4: 1:15; 2:7; 8:24
A5: 1271571 | B5: RONDON BARRUTIA CHRISTIAN ERIC | D5: 45950 | E5: 46315 | F5: 45 | G5: 45 | H5: 21 | I5: 2:6; 3:1; 5:7; 8:7
A6: 2369624 | B6: NAJAR CRUZ PATRICIA DEL PILAR | C6: 39187 | D6: 45762 | E6: 46127 | F6: 44 | G6: 45 | H6: 42 | I6: 1:6; 4:7; 8:7; 9:7; 10:15
A7: 2369641 | B7: TORRES POLO ELIZABETH DEL PILAR | C7: 39197 | D7: 45772 | E7: 46137 | F7: 44 | G7: 45 | H7: 42 | I7: 1:12; 6:8; 9:15; 11:7
A8: 2396710 | B8: CORREA GARCIA JUAN SEBASTIAN | D8: 45823 | E8: 46188 | F8: 43 | G8: 45 | H8: 31 | I8: 4:18; 6:8; 11:5
A9: 2415373 | B9: SALAS COSIO MILAGROS PATRICIA | C9: 39295 | D9: 45870 | E9: 46235 | F9: 44 | G9: 45 | H9: 44 | I9: 5:29; 10:15
A10: 2440915 | B10: FERNANDEZ GARCIA JUDITH JULIET | C10: 39356 | D10: 45931 | E10: 46296 | F10: 44 | G10: 45 | H10: 44 | I10: 1:7; 2:14; 8:15; 10:8
A11: 2604360 | B11: CARRASCO BENAVIDES ROSA MARIELLA | C11: 40301 | D11: 45780 | E11: 46145 | F11: 41 | G11: 42 | H11: 40 | I11: 2:10; 5:8; 9:15; 11:7
A12: 2713993 | B12: RUIZ RIOJA FIORELLA DEL PILAR | D12: 45689 | E12: 46054 | F12: 45 | G12: 45 | H12: 41 | I12: 3:5; 5:2; 7:1; 10:29; 11:4
A13: 2823133 | B13: CAMPOS CONCHE CESAR AUGUSTO | C13: 40546 | D13: 45660 | E13: 46025 | F13: 40 | G13: 41 | H13: 41 | I13: 6:15; 7:15; 12:11
A14: 2843319 | B14: SANTA CRUZ HUAMAN KAREN | C14: 40026 | D14: 45870 | E14: 46235 | F14: 42 | G14: 43 | H14: 42 | I14: 1:14; 7:12; 10:16
A15: 3134911 | B15: ZAPATA GARAYAR JAVIER RICARDO SALVADOR | C15: 40462 | D15: 45941 | E15: 46306 | F15: 41 | G15: 42 | H15: 46 | I15: 3:23; 10:23
A16: 3189967 | B16: SEGOVIA TAPIA RAY KEVIN | C16: 40546 | D16: 45660 | E16: 46025 | F16: 40 | G16: 41 | H16: 41 | I16: 6:7; 8:16; 9:18
A17: 3217561 | B17: FLORES FUENTES DAVILA CLAUDIA ALEXANDRA | C17: 40567 | D17: 45681 | E17: 46046 | F17: 40 | G17: 41 | H17: 41 | I17: 4:15; 9:15; 11:11
A18: 3750335 | B18: MENDEZ RUCOBA JEFFERSON JOHONATAN | C18: 42186 | D18: 45839 | E18: 46204 | F18: 36 | G18: 37 | H18: 35 | I18: 4:20; 9:8; 11:7
A19: 3779550 | B19: ACURIO DARGENT JENNIFERT MILAGROS | C19: 41470 | D19: 45853 | E19: 46218 | F19: 38 | G19: 39 | H19: 38 | I19: 4:8; 6:15; 11:15
A20: 3796947 | B20: RAFAEL ANTONIO NIETO | C20: 41526 | F20: 38 | G20: 39 | H20: 8 | I20: 9:8
A21: 3841387 | B21: CELIZ ROSSI GIANFRANCO PAOLO | C21: 41656 | D21: 45674 | E21: 46039 | F21: 37 | G21: 38 | H21: 39 | I21: 1:8; 6:7; 7:17; 8:7
A22: 3852423 | B22: UNGARO GUTIERREZ SARA GABRIELA | C22: 41835 | D22: 45853 | E22: 46218 | F22: 37 | G22: 38 | H22: 39 | I22: 3:8; 5:8; 6:7; 8:16

Sheet VacacionesDias
A1: BP | B1: Fecha
A2: 29530 | B2: 45299
A3: 29530 | B3: 45300
A4: 29530 | B4: 45301
A5: 29530 | B5: 45302
A6: 29530 | B6: 45303
A7: 29530 | B7: 45304
A8: 29530 | B8: 45305
A9: 29530 | B9: 45306
A10: 29530 | B10: 45307
A11: 29530 | B11: 45308
A12: 29530 | B12: 45309
A13: 29530 | B13: 45310
... A2325: 3852423 | B2325: 46257

Sheet VacacionesBloques
A1: BP | B1: Desde | C1: Hasta | D1: Días | E1: Registrado
A2: 29530 | B2: 46296 | C2: 46310 | D2: 15 | E2: 46230
A3: 29530 | B3: 46377 | C3: 46387 | D3: 11 | E3: 46230
A4: 1271571 | B4: 46279 | C4: 46313 | D4: 24 | E4: 46227
A5: 2369624 | B5: 46296 | C5: 46310 | D5: 15 | E5: 46230
A6: 2369624 | B6: 46266 | C6: 46272 | D6: 7 | E6: 46230
A7: 2369641 | B7: 46282 | C7: 46295 | D7: 14 | E7: 46230
A8: 2369641 | B8: 46349 | C8: 46356 | D8: 8 | E8: 46230
A9: 2415373 | B9: 46300 | C9: 46307 | D9: 8 | E9: 46234
A10: 2415373 | B10: 46308 | C10: 46314 | D10: 7 | E10: 46235
A11: 2440915 | B11: 46303 | C11: 46310 | D11: 8 | E11: 46230
A12: 2604360 | B12: 46281 | C12: 46295 | D12: 15 | E12: 46233
A13: 2604360 | B13: 46381 | C13: 46387 | D13: 7 | E13: 46233
... A24: 3779550 | B24: 46328 | C24: 46342 | D24: 15 | E24: 46237

Sheet SolicitudesVacaciones
A1: ID | B1: BP | C1: Nombre | D1: Días | E1: Cantidad | F1: Enviada | G1: Estado | H1: Decidida | I1: Decidida por

Sheet Roles
A1: mes | B1: json | C1: actualizadoAt | D1: origen
A2: 2026-01 | B2: {"hoja":"ENERO","fuente":"10 - Rol_Instructores_LP_OCTUBRE_1.xlsx","mes":"2026-01","instructores":[{"dias":["B","LCK B767\n- LIM-BOG\n- LA 2489 (13:00-16:15 hrs)\nLCK B767\n- BOG-LIM\n- LA 2488 (17:20-20:45 hrs)","FDS","FDS","LCK B767\n- LIM-MIA\n- LA 2694 (13:30-19:30 hrs)","Blanco","Reentrenamiento B767\n- MIA-LIM\n- LA 2699 (23:10-05:00 hrs)","Reva de Servicio\n(08:30-17:30 hrs)\nDÍA 1","Reva de Servicio\n(08:30-17:30 hrs)\nDÍA 2","FDS","FDS","LCK B787\n- LIM-SCL\n- LA 2697 (09:35-13:00 hrs)\nRECALIFICACIÓN B787\n- SCL-LIM\n- LA 2696 (16:00-19:45 hrs)","RESERVA IET Tarde","LCK B787\n- LIM-SCL\n- LA 2697 (09:35-13:00 hrs)\nLCK B787\n- SCL-LIM\n- LA 2696 (16:00-19:45 hrs)","Inicial G13\nTARDE","Inicial G13","FDS","FDS","LCK B767\n- LIM-MIA\n- LA 2694 (13:30-19:30 hrs)","Blanco","Reentrenamiento B767\n- MIA-LIM\n- LA 2699 (23:10-05:00 hrs)","Inicial G3","HANDS ON B767","FDS","FDS","HO FILE","Inicial G3","CHEQUEO LATAM B787\n- LIM-SCL\n- LA 2697 (09:35-13:00 hrs)\nCHEQUEO LATAM B787\n- SCL-LIM\n- LA 2696 (16:00-19:45 hrs)","RESERVA IET Tarde","RESERVA IET","FDS"],"nombre":"Fiorella Ruiz","bp":"2713993"},{"nombre":"Sebastian Correa","dias":["DO","RESERVA IET","FDS","FDS","RESERVA IET","Habilitación B787\n- LIM-SCL\n- LA 2697 (09:35-13:00 hrs)\nPD\n- SCL-LIM\n- LA 2696 (16:00-19:45 hrs)","RESERVA IET Tarde","LCK B767\n- LIM-BOG\n- LA 2489 (13:00-16:15 hrs)\nLCK B767\n- BOG-LIM\n- LA 2488 (17:20-20:45 hrs)","RESERVA IET Tarde","FDS","FDS","TALLER VOLUNTARIO SEG","Inicial G2","RTI: PRÁCTICA\nA320F / B767 / B787\n(08:30-17:30 hrs)\nINS APOYO","Inicial G13","Inicial G2","FDS","FDS","LCK B787\n- LIM-SCL\n- LA 2697 (09:35-13:00 hrs)\nLCK B787\n- SCL-LIM\n- LA 2696 (16:00-19:45 hrs)","RESERVA IET Tarde","LCK B787\n- LIM-SCL\n- LA 2697 (09:35-13:00 hrs)\nLCK B787\n- SCL-LIM\n- LA 2696 (16:00-19:45 hrs)","RESERVA IET Tarde","RESERVA IET","FDS","FDS","CHEQUEO DGAC B787\n- LIM-SCL\n- LA 2697 (09:35-13:00 hrs)\nCHEQUEO DGAC B787\n- SCL-LIM\n- LA 2696 (16:00-19:45 hrs)","RESERVA IET Tarde","HO FILE","HANDS ON B787","CHEQUEO DGAC B787\n- LIM-SCL\n- LA 2697 (09:35-13:00 hrs)\nPD B787\n- SCL-LIM\n- LA 2696 (16:00-19:45 hrs)","FDS"],"bp":"2396710"},{"bp":"1271571","dias":["DO","TTT RRVV\nINS","FDS","FDS","LCK B787\n- LIM-SCL\n- LA 2697 (09:35-13:00 hrs)\nLCK B787\n- SCL-LIM\n- LA 2696 (16:00-19:45 hrs)","RESERVA IET Tarde","LCK B787\n- LIM-SCL\n- LA 2697 (09:35-13:00 hrs)\nLCK B787\n- SCL-LIM\n- LA 2696 (16:00-19:45 hrs)","RESERVA IET Tarde","Inicial G3","FDS","FDS","RESERVA IET","CHEQUEO LATAM B787\n- LIM-SCL\n- LA 2697 (09:35-13:00 hrs)\nCHEQUEO LATAM B787\n- SCL-LIM\n- LA 2696 (16:00-19:45 hrs)","RESERVA IET Tarde","RTI: PRÁCTICA\nA320F / B767 / B787\n(08:30-17:30 hrs)\nINS APOYO TM","Inicial G13","FDS","FDS","Blanco Recojo","LCK B767\n- LIM-MIA\n- LA 2480 (00:15-06:15 hrs)","PD\n- MIA-LIM\n- LA 2481 (15:55-21:40 hrs)","RESERVA IET Tarde","HANDS ON B787","FDS","FDS","LCK B767\n- LIM-MIA\n- LA 2694 (13:30-19:30 hrs)","Blanco","PD\n- MIA-LIM\n- LA 2699 (23:10-05:00 hrs)","HO FILE","TTT RRVV\nINS","FDS"],"nombre":"Christian Rondon"},{"dias":["DO","TTT RRVV\nALUMNO","DO","DO","Blanco Recojo","LCK B767\n- LIM-MIA\n- LA 2480 (00:15-06:15 hrs)","PD\n- MIA-LIM\n- LA 2481 (15:55-21:40 hrs)","RESERVA IET Tarde","RTI: PRÁCTICA\nA320F / B767\n(08:30-17:30 hrs)\nINS APOYO","DO","DO","HO FILE","AUDITORIA PROCAB","Inicial G13","DO","VACACIONES","VACACIONES","VACACIONES","VACACIONES","VACACIONES","VACACIONES","VACACIONES","VACACIONES","VACACIONES","VACACIONES","VACACIONES","VACACIONES","VACACIONES","VACACIONES","VACACIONES","VACACIONES"],"bp":"2843319","nombre":"Karen Santa Cruz"},{"bp":"3779550","dias":["DO","DO","DO","DO","RESERVA IET","LCK A320F\nLIM-AQP-LIM\nLA 2123 (09:20-11:00 hrs)\nLA 2124 (11:35-13:10 hrs)\nLCK A320F\nLIM-PCL-LIM\nLA 2360 (14:05-15:20 hrs)\nLA 2361 (15:55-17:10 hrs)","RESERVA IET","Inicial G3","RTI: PRÁCTICA\nA320F / B767\n(08:30-17:30 hrs)\nINS TITULAR","DO","DO","HAB B787","RESERVA IET Tarde","Inicial G13","LCK B767\n- LIM-BOG\n- LA 2489 (13:00-16:15 hrs)\nLCK B767\n- BOG-LIM\n- LA 2488 (17:20-20:45 hrs)","RESERVA IET Tarde","DO","DO","Inicial G13","Blanco Recojo","LCK B767\n- LIM-MIA\n- LA 2480 (00:15-06:15 hrs)","PD\n- MIA-LIM\n- LA 2695 (16:20-22:00 hrs)","RESERVA IET Tarde","DO","DO","HO FILE","Inicial G3","Blanco Recojo","LCK B767\n- LIM-MIA\n- LA 2480 (00:15-06:15 hrs)","Habilitación B767\n- MIA-LIM\n- LA 2481 (15:55-21:40 hrs)","DO"],"nombre":"Jennifert Acurio"},{"nombre":"Jazmin Guerra","dias":["DO","HO FILE","DO","DO","Inicial G13","Inicial G2","HAB B787","DO","DO","DO","DO","LCK B767\n- LIM-MIA\n- LA 2694 (13:30-19:30 hrs)","Blanco","PD\n- MIA-LIM\n- LA 2699 (23:10-05:00 hrs)","RTI: PRÁCTICA\nA320F / B767 / B787\n(08:30-17:30 hrs)\nINS APOYO TM","LCK B767\n- LIM-BOG\n- LA 2489 (13:00-16:15 hrs)\nLCK B767\n- BOG-LIM\n- LA 2488 (17:20-20:45 hrs)","DO","DO","Inicial G13","Inicial G13","Blanco Recojo","LCK B767\n- LIM-MIA\n- LA 2480 (00:15-06:15 hrs)","PD\n- MIA-LIM\n- LA 2481 (15:55-21:40 hrs)","DO","DO","Situaciones de Emergencia B767\nTripulación de Mando\nLP\n(08:30-17:30 hrs)","HO FILE","Ditching Presencial B767 + HANDS ON\nTripulación de Mando\nLP\n(08:30-17:30 hrs)","Reva de Servicio\n(08:30-17:30 hrs)\nDÍA 1","Reva de Servicio\n(08:30-17:30 hrs)\nDÍA 2","DO"],"bp":"29530"},{"dias":["DO","DO","DO","DO","LCK A320F\nLIM-CUZ-LIM\nLA 2007 (09:15-10:45 hrs)\nLA 2008 (11:20-12:55 hrs)\nLCK A320F\nLIM-AQP-LIM\nLA 2115 (13:55-15:25 hrs)\nLA 2114 (16:00-17:35 hrs)","RESERVA IET","LCK A320F\nLIM-TCQ-LIM\nLA 2245 (09:00-10:50 hrs)\nLA 2244 (11:25-13:15 hrs)\nLCK A320F\nLIM-TPP-LIM\nLA 2087 (14:10-15:35 hrs)\nLA 2088 (16:10-17:30 hrs)","Inicial G2","Inicial G2","DO","DO","TALLER VOLUNTARIO SEG","HANDS ON B767","Inicial G13","Inicial G2","HAB B767 (CST)","DO","DO","LCK A320F\nLIM-AQP-LIM\nLA 2123 (09:20-11:00 hrs)\nLA 2124 (11:35-13:10 hrs)\nLCK A320F\nLIM-CUZ-LIM\nLA 2075 (14:25-15:50 hrs)\nLA 2076 (16:25-18:00 hrs)","LCK ALUMNO","Inicial G3","Inicial G13","LCK A320F\nLIM-AQP-LIM\nLA 2123 (09:20-11:00 hrs)\nLA 2124 (11:35-13:10 hrs)\nLCK A320F\nLIM-CIX-LIM\nLA 2312 (14:25-15:55 hrs)\nLA 2313 (16:35-18:00 hrs)","DO","DO","LCK A320F\nLIM-CUZ-LIM\nLA 2007 (09:15-10:45 hrs)\nLA 2008 (11:20-12:55 hrs)\nLCK A320F\nLIM-AQP-LIM\nLA 2115 (13:55-15:25 hrs)\nLA 2114 (16:00-17:35 hrs)","HO FILE","LCK A320F\nLIM-AQP-LIM\nLA 2123 (09:20-11:00 hrs)\nLA 2124 (11:35-13:10 hrs)\nLCK A320F\nLIM-PCL-LIM\nLA 2360 (14:05-15:20 hrs)\nLA 2361 (15:55-17:10 hrs)","Inicial G2","LCK A320F\nLIM-AQP-LIM\nLA 2123 (09:20-11:00 hrs)\nLA 2124 (11:35-13:10 hrs)\nLCK A320F\nLIM-TPP-LIM\nLA 2087 (14:10-15:35 hrs)\nLA 2088 (16:10-17:30 hrs)","DO"],"nombre":"Claudia Flores","bp":"3217561"},{"nombre":"Luis Bacigalupo","dias":["DO","HO FILE","DO","DO","RESERVA IET","LCK A320F\nLIM-TCQ-LIM\nLA 2245 (09:00-10:50 hrs)\nLA 2244 (11:25-13:15 hrs)\nLCK A320F\nLIM-TPP-LIM\nLA 2087 (14:10-15:35 hrs)\nLA 2088 (16:10-17:30 hrs)","Inicial G2","DO","DO","DO","DO","Blanco Recojo","LCK B767\n- LIM-MIA\n- LA 2480 (00:15-06:15 hrs)","LCK B767\n- MIA-LIM\n- LA 2481 (15:55-21:40 hrs)","Inicial G13\nTARDE","Inicial G13","DO","DO","Inicial G2","Reva de Servicio\n(08:30-17:30 hrs)\nDÍA 1","Reva de Servicio\n(08:30-17:30 hrs)\nDÍA 2","LCK B767\n- LIM-BOG\n- LA 2489 (13:00-16:15 hrs)\nLCK B767\n- BOG-LIM\n- LA 2488 (17:20-20:45 hrs)","RESERVA IET Tarde","DO","DO","Inicial G13","Blanco Recojo","LCK B767\n- LIM-MIA\n- LA 2480 (00:15-06:15 hrs)","PD\n- MIA-LIM\n- LA 2695 (16:20-22:00 hrs)","RESERVA IET Tarde","DO"],"bp":"2963161"},{"dias":["LP","LP","LP","LP","LP","LP","LP","LP","LP","LP","LP","LP","LP","LP","LP","LP","LP","LP","LP","LP","LP","LP","LP","LP","LP","LP","LP","LP","LP","LP","LP"],"bp":"71348","nombre":"Karla Moz"},{"bp":"967092","dias":["VACACIONES","VACACIONES","VACACIONES","VACACIONES","VACACIONES","VACACIONES","VACACIONES","RESERVA IET","RTI: PRÁCTICA\nA320F / B767\n(08:30-17:30 hrs)\nINS APOYO TM","DO","DO","Inicial G3","RTI: VIRTUAL\nA320F / B767 / B787\n(08:30-17:30 hrs)\nINS TITULAR","RTI: PRÁCTICA\nA320F / B767 / B787\n(08:30-17:30 hrs)\nINS TITULAR","RTI: PRÁCTICA\nA320F / B767 / B787\n(08:30-17:30 hrs)\nINS TITULAR","Inicial G13","DO","DO","Inicial G13","Inicial G13","Inicial G13","Inicial G2","DO","VACACIONES","VACACIONES","VACACIONES","VACACIONES","VACACIONES","VACACIONES","VACACIONES","VACACIONES"],"nombre":"Erika Dávila"},{"dias":["VACACIONES","VACACIONES","VACACIONES","VACACIONES","VACACIONES","VACACIONES","VACACIONES","VACACIONES","VACACIONES","VACACIONES","VACACIONES","VACACIONES","Blanco Recojo","LCK B767\n- LIM-MIA\n- LA 2480 (00:15-06:15 hrs)","PD\n- MIA-LIM\n- LA 2695 (16:20-22:00 hrs)","RESERVA IET Tarde","DO","DO","HO FILE","Inicial G13","Inicial G13","HAB NB","LCK B767\n- LIM-BOG\n- LA 2489 (13:00-16:15 hrs)\nLCK B767\n- BOG-LIM\n- LA 2488 (17:20-20:45 hrs)","DO","DO","Blanco Recojo","LCK B767\n- LIM-MIA\n- LA 2480 (00:15-06:15 hrs)","PD\n- MIA-LIM\n- LA 2481 (15:55-21:40 hrs)","RESERVA IET Tarde","TTT RRVV\nALUMNO","DO"],"nombre":"Elizabeth Torres","bp":"2369641"},{"bp":"2369624","nombre":"Patricia del Pilar Najar","dias":["VACACIONES","VACACIONES","VACACIONES","VACACIONES","VACACIONES","VACACIONES","NME","NME","NME","NME","NME","NME","NME","NME","NME","NME","NME","NME","NME","NME","NME","NME","NME","NME","NME","NME","NME","NME","NME","NME","NME"]},{"nombre":"Javier Zapata","bp":"3134911","dias":["DO","Inicial G13","DO","DO","RESERVA IET","LCK ALUMNO","Inicial G3","DO","DO","DO","DO","Inicial G2","LCK B767\n- LIM-MIA\n- LA 2698 (08:25-14:20 hrs)","Blanco","PD\n- MIA-LIM\n- LA 2699 (23:10-05:00 hrs)","Inicial G13","DO","DO","Inicial G3","Inicial G3","Inicial G13","RTI: PRÁCTICA\nA320F / B767\n(08:30-17:30 hrs)\nINS APOYO TM","Inicial G13","DO","DO","RESERVA IET","HO FILE","Inicial G3","LCK B767\n- LIM-BOG\n- LA 2489 (13:00-16:15 hrs)\nLCK B767\n- BOG-LIM\n- LA 2488 (17:20-20:45 hrs)","RESERVA IET Tarde","DO"]},{"bp":"3750335","nombre":"Jefferson Mendez","dias":["DO","RESERVA IET","DO","DO","LCK A320F\nLIM-AQP-LIM\nLA 2123 (09:20-11:00 hrs)\nLA 2124 (11:35-13:10 hrs)\nLCK A320F\nLIM-TPP-LIM\nLA 2087 (14:10-15:35 hrs)\nLA 2088 (16:10-17:30 hrs)","RESERVA IET","LCK A320F\nLIM-AQP-LIM\nLA 2123 (09:20-11:00 hrs)\nLA 2124 (11:35-13:10 hrs)\nLCK A320F\nLIM-PCL-LIM\nLA 2360 (14:05-15:20 hrs)\nLA 2361 (15:55-17:10 hrs)","DO","DO","DO","DO","LCK A320F\nLIM-TCQ-LIM\nLA 2245 (09:00-10:50 hrs)\nLA 2244 (11:25-13:15 hrs)\nLCK A320F\nLIM-TPP-LIM\nLA 2087 (14:10-15:35 hrs)\nLA 2088 (16:10-17:30 hrs)","Inicial G3","Blanco Recojo","LCK B767\n- LIM-MIA\n- LA 2480 (00:15-06:15 hrs)","PD\n- MIA-LIM\n- LA 2481 (15:55-21:40 hrs)","DO","DO","TALLER VOLUNTARIO SEG","Reentrenamiento A320F\nLIM-AQP-LIM\nLA 2123 (09:20-11:00 hrs)\nLA 2124 (11:35-13:10 hrs)\nLCK A320F\nLIM-PCL-LIM\nLA 2360 (14:05-15:20 hrs)\nLA 2361 (15:55-17:10 hrs)","RESERVA IET","Inicial G13","Inicial G13","DO","DO","LCK A320F\nLIM-AQP-LIM\nLA 2123 (09:20-11:00 hrs)\nLA 2124 (11:35-13:10 hrs)\nLCK A320F\nLIM-TPP-LIM\nLA 2087 (14:10-15:35 hrs)\nLA 2088 (16:10-17:30 hrs)","Inicial G2","HO FILE","Inicial G13","LCK B767\n- LIM-BOG\n- LA 2489 (13:00-16:15 hrs)\nLCK B767\n- BOG-LIM\n- LA 2488 (17:20-20:45 hrs)","DO"]},{"nombre":"Gabriela Ungaro","dias":["DO","HO FILE","DO","DO","RESERVA IET","Reva de Servicio\n(08:30-17:30 hrs)\nDÍA 1","RESERVA IET","DO","DO","DO","DO","LCK A320F\nLIM-AQP-LIM\nLA 2123 (09:20-11:00 hrs)\nLA 2124 (11:35-13:10 hrs)\nLCK A320F\nLIM-CUZ-LIM\nLA 2075 (14:25-15:50 hrs)\nLA 2076 (16:25-18:00 hrs)","Inicial G13","Inicial G2","ACT\nRRVV","CHEQUEO DGAC A320F\nLIM-AQP-LIM\nLA 2123 (09:20-11:00 hrs)\nLA 2124 (11:35-13:10 hrs)","DO","DO","TALLER VOLUNTARIO SEG","Inicial G2","Inicial G13","LCK A320F\nLIM-AQP-LIM\nLA 2123 (09:20-11:00 hrs)\nLA 2124 (11:35-13:10 hrs)\nLCK A320F\nLIM-TPP-LIM\nLA 2087 (14:10-15:35 hrs)\nLA 2088 (16:10-17:30 hrs)","Inicial G3","DO","DO","Recalificación A320F\nLIM-CUZ-LIM\nLA 2238 (10:15-11:40 hrs)\nLA 2239 (12:15-13:45 hrs)","LCK B767\n- LIM-MIA\n- LA 2698 (08:25-14:20 hrs)","Blanco","Reentrenamiento B767\n- MIA-LIM\n- LA 2699 (23:10-05:00 hrs)","LCK A320F\nLIM-PIU-LIM\nLA 2306 (09:35-11:20 hrs)\nLA 2307 (11:55-13:25 hrs)\nLCK A320F\nLIM-CIX-LIM\nLA 2312 (14:25-15:55 hrs)\nLA 2313 (16:35-18:00 hrs)","DO"],"bp":"3852423"},{"nombre":"Mariella Carrasco","dias":["DO","DO","DO","DO","Inicial G13","Inicial G13","Reva de Servicio\n(08:30-17:30 hrs)\nDÍA 2","RESERVA IET","RESERVA IET","DO","DO","LCK A320F\nLIM-CIX-LIM\nLA 2274 (09:40-11:10 hrs)\nLA 2275 (11:45-13:05 hrs)\nLCK A320F\nLIM-AQP-LIM\nLA 2115 (13:55-15:25 hrs)\nLA 2114 (16:00-17:35 hrs)","Inicial G13","Inicial G3","ACT\nRRVV","LCK ALUMNA","DO","DO","HO FILE","LCK B767\n- LIM-MIA\n- LA 2698 (08:25-14:20 hrs)","Blanco","Recalificación B767\n- MIA-LIM\n- LA 2699 (23:10-05:00 hrs)","RESERVA IET","DO","DO","HO FILE","Reva de Servicio\n(08:30-17:30 hrs)\nDÍA 1","Reva de Servicio\n(08:30-17:30 hrs)\nDÍA 2","Inicial G3","RESERVA IET","DO"],"bp":"2604360"},{"dias":["DO","Inicial G13","DO","DO","Reentrenamiento B767\n- LIM-MIA\n- LA 2694 (13:30-19:30 hrs)","Blanco","PD\n- MIA-LIM\n- LA 2699 (23:10-05:00 hrs)","DO","DO","DO","DO","RESERVA IET","Inicial G13","HAB B767","HAB B767","HAB B767","DO","DO","Inicial G13","RTI: VIRTUAL\nA320F / B767\n(08:30-17:30 hrs)\nINS TITULAR","Inicial G2","RTI: PRÁCTICA\nA320F / B767\n(08:30-17:30 hrs)\nINS TITULAR","Inicial G2","DO","DO","HANDS ON B767","HO FILE","RESERVA IET","RTI: PRÁCTICA\nA320F / B767\n(08:30-17:30 hrs)\nINS TITULAR","Inicial G3","DO"],"bp":"2823133","nombre":"Cesar Campos"},{"bp":"3189967","nombre":"Kevin Segovia","dias":["DO","HO FILE","DO","DO","LCK ALUMNO","RESERVA IET","RTI: VIRTUAL\nA320F / B767\n(08:30-17:30 hrs)\nINS CRM","DO","DO","DO","DO","RESERVA IET","CHEQUEO LATAM A320F\nLIM-TCQ-LIM\nLA 2245 (09:00-10:50 hrs)\nLA 2244 (11:25-13:15 hrs)","Inicial G13","Inicial G3","Inicial G3","DO","DO","RESERVA IET","Inicial G13","HAB B767","HAB B767","HAB B767","DO","DO","RESERVA IET","RESERVA IET","RESERVA IET","HO FILE","RESERVA IET","DO"]},{"dias":["DO","HO FILE","DO","DO","RESERVA IET","RESERVA IET","RTI: VIRTUAL\nA320F / B767\n(08:30-17:30 hrs)\nINS TITULAR","DO","DO","DO","DO","RESERVA IET","Reva de Servicio\n(08:30-17:30 hrs)\nDÍA 1","Reva de Servicio\n(08:30-17:30 hrs)\nDÍA 2","Reva de Servicio\n(08:30-17:30 hrs)\nDÍA 1","Reva de Servicio\n(08:30-17:30 hrs)\nDÍA 2","DO","DO","Inicial G13","Inicial G13","RESERVA IET","Reva de Servicio\n(08:30-17:30 hrs)\nDÍA 1","Reva de Servicio\n(08:30-17:30 hrs)\nDÍA 2","DO","DO","HAB B767","HAB B767","HAB B767","RTI: PRÁCTICA\nA320F / B767\n(08:30-17:30 hrs)\nINS APOYO","Inicial G13","DO"],"bp":"2415373","nombre":"Milagros Salas"},{"nombre":"Judith Fernandez","dias":["VACACIONES","VACACIONES","VACACIONES","VACACIONES","VACACIONES","VACACIONES","VACACIONES","DO","DO","DO","DO","RESERVA IET","RESERVA IET","RESERVA IET","RTI: PRÁCTICA\nA320F / B767 / B787\n(08:30-17:30 hrs)\nINS APOYO","RESERVA IET","DO","DO","Inicial G13","RTI: VIRTUAL\nA320F / B767\n(08:30-17:30 hrs)\nINS CRM","RESERVA IET","RTI: PRÁCTICA\nA320F / B767\n(08:30-17:30 hrs)\nINS APOYO","RESERVA IET","DO","DO","Inicial G2","RTI: VIRTUAL\nA320F / B767\n(08:30-17:30 hrs)\nINS CRM","Inicial G2","HO FILE","DO","DO"],"bp":"2440915"},{"bp":"3796947","dias":["SICK","SICK","SICK","SICK","SICK","CUMP","CUMP","SICK","SICK","SICK","SICK","SICK","SICK","SICK","SICK","SICK","SICK","SICK","SICK","SICK","SICK","SICK","SICK","SICK","SICK","SICK","SICK","SICK","SICK","SICK","SICK"],"nombre":"Rafael Nieto"},{"dias":["DO","RESERVA IET","DO","DO","RESERVA IET","RESERVA IET","RESERVA IET","DO","DO","DO","DO","RESERVA IET","RTI: VIRTUAL\nA320F / B767 / B787\n(08:30-17:30 hrs)\nINS CRM","Inicial G13","DO","VACACIONES","VACACIONES","VACACIONES","VACACIONES","VACACIONES","VACACIONES","VACACIONES","VACACIONES","DO","DO","Inicial G3","RTI: VIRTUAL\nA320F / B767\n(08:30-17:30 hrs)\nINS TITULAR","RESERVA IET","HO FILE","Inicial G2","DO"],"bp":"3841387","nombre":"Gianfranco Celiz"}]} | C2: 46296.54
A3: 2026-02 | B3: {"instructores":[{"dias":["FDS","Inicial G3","HO FILE","Inicial G3","Inicial G3","Inicial G2","FDS","FDS","TALLER 2026 - CONSTRUIR","HANDS ON\nB787","Inicial G4","LCK ALUMNA","REUNIÓN INSTRUCTORES\nTARDE","FDS","FDS","LCK B787\n- LIM-SCL\n- LA 2697 (09:35-13:00 hrs)\nLCK B787\n- SCL-LIM\n- LA 2696 (16:00-19:45 hrs)","RESERVA IET\nTARDE","RTI: PRÁCTICA\nA320F / B767 / B787\n(08:30-17:30 hrs)\nINS APOYO","Inicial G3","LCK B767\n- LIM-BOG\n- LA 2489 (13:00-16:15 hrs)\nLCK B767\n- BOG-LIM\n- LA 2488 (17:20-20:45 hrs)","FDS","FDS","LCK B767\n- LIM-MIA\n- LA 2694 (13:30-19:30 hrs)","Blanco","Chequeo DGAC B767\n- MIA-LIM\n- LA 2699 (23:10-05:00 hrs)","Inicial G2","Inicial G4","FDS"],"bp":"2713993","nombre":"Fiorella Ruiz"},{"bp":"2396710","dias":["FDS","LCK B767\n- LIM-MIA\n- LA 2694 (13:30-19:30 hrs)","Blanco","Chequeo LATAM B767\n- MIA-LIM\n- LA 2699 (23:10-05:00 hrs)","RTI: PRÁCTICA\nA320F / B767 / B787\n(08:30-17:30 hrs)\nINS TITULAR\nAPOYO TM","LCK A320F\nLIM-AQP-LIM\nLA 2119 (08:40-10:10 hrs)\nLA 2118 (10:45-12:10 hrs)\nLCK A320F\nLIM-PIU-LIM\nLA 2308 (13:10-14:50 hrs)\nLA 2309 (15:25-16:55 hrs)","FDS","FDS","TALLER 2026 - CONSTRUIR","LCK A320F\nLIM-CUZ-LIM\nLA 2232 (08:35-10:05 hrs)\nLA 2233 (10:40-12:15 hrs)\nLCK A320F\nLIM-CUZ-LIM\nLA 2075 (13:25-14:50 hrs)\nLA 2076 (15:25-16:45 hrs)","Blanco Recojo","LCK B767\n- LIM-MIA\n- LA 2480 (00:15-06:15 hrs)","Chequeo LATAM B767\n- MIA-LIM\n- LA 2481 (15:55-21:40 hrs)","FDS","FDS","PD\nLIM-CUZ-LIM\nLA 2232 (08:35-10:05 hrs)\nLA 2233 (10:40-12:15 hrs)\nReentrenamiento A320F\nLIM-CIX-LIM\nLA 2312 (13:25-14:50 hrs)\nLA 2313 (15:25-16:45 hrs)","Inicial G1","Inicial G4","LCK A320F\nLIM-AQP-LIM\nLA 2119 (08:40-10:10 hrs)\nLA 2118 (10:45-12:10 hrs)\nLCK A320F\nLIM-PIU-LIM\nLA 2308 (13:10-14:50 hrs)\nLA 2309 (15:25-16:55 hrs)","Chequeo BI Anual INST B767\n- LIM-BOG\n- LA 2489 (13:00-16:15 hrs)\nPD\n- BOG-LIM\n- LA 2488 (17:20-20:45 hrs)","FDS","FDS","LCK B767\n- LIM-MIA\n- LA 2698 (08:25-14:20 hrs)","Recalificación B767\n- MIA-LIM\n- LA 2481 (15:55-21:40 hrs)","HO FILE\nTARDE","LCK B787\n- LIM-SCL\n- LA 2697 (09:35-13:00 hrs)\nLCK B787\n- SCL-LIM\n- LA 2696 (16:00-19:45 hrs)","HO FILE\nTARDE","FDS"],"nombre":"Sebastian Correa"},{"dias":["FDS","RTI ALUMNO","RTI: VIRTUAL\nA320F / B767 / B787\n(08:30-17:30 hrs)\nINS TITULAR\n*Se habilita","RTI: PRÁCTICA\nA320F / B767 / B787\n(08:30-17:30 hrs)\nINS TITULAR\n*Se habilita","RTI: PRÁCTICA\nA320F / B767 / B787\n(08:30-17:30 hrs)\nINS TITULAR\n*Se habilita","RTI ALUMNO","FDS","FDS","TALLER 2026 - CONSTRUIR","HO FILE","RTI: PRÁCTICA\nA320F / B767 / B787\n(08:30-17:30 hrs)\nINS APOYO","LCK B787\n- LIM-SCL\n- LA 2697 (09:35-13:00 hrs)\nLCK B787\n- SCL-LIM\n- LA 2696 (16:00-19:45 hrs)","REUNIÓN INSTRUCTORES\nTARDE","FDS","FDS","Blanco Recojo","LCK B767\n- LIM-MIA\n- LA 2480 (00:15-06:15 hrs)","Chequeo LATAM B767\n- MIA-LIM\n- LA 2481 (15:55-21:40 hrs)","RESERVA IET\nTARDE","Chequeo BI Anual INST B767\n- LIM-BOG\n- LA 2489 (13:00-16:15 hrs)\nPD\n- BOG-LIM\n- LA 2488 (17:20-20:45 hrs)","FDS","FDS","VACACIONES","VACACIONES","VACACIONES","VACACIONES","VACACIONES","VACACIONES"],"nombre":"Christian Rondon","bp":"1271571"},{"nombre":"Karen Santa Cruz","dias":["DO","Blanco Recojo","LCK B767\n- LIM-MIA\n- LA 2480 (00:15-06:15 hrs)","Chequeo LATAM B767\n- MIA-LIM\n- LA 2481 (15:55-21:40 hrs)","RESERVA IET\nTARDE","Inicial G4","DO","DO","TALLER 2026 - CONSTRUIR","HO FILE","LCK A320F\nLIM-CUZ-LIM\nLA 2232 (08:35-10:05 hrs)\nLA 2233 (10:40-12:15 hrs)\nLCK A320F\nLIM-CIX-LIM\nLA 2312 (13:25-14:50 hrs)\nLA 2313 (15:30-16:50 hrs)","Inicial G1","Inicial G3","DO","DO","HABILITACIÓN A320","LCK B767\n- LIM-MIA\n- LA 2698 (08:25-14:20 hrs)","Blanco","Chequeo LATAM B767\n- MIA-LIM\n- LA 2699 (23:10-05:00 hrs)","Inicial G2","DO","DO","DO","DO","Inicial G2","Inicial G2","Inicial G2","DO"],"bp":"2843319"},{"dias":["DO","HO FILE","DITCHING TM\nINS","TALLER VOLUNTARIO","Inicial G13","Inicial G13","DO","DO","TALLER 2026 - CONSTRUIR","TALLER VOLUNTARIO","HABILITACIÓN A320","Inicial G4","REUNIÓN INSTRUCTORES","DO","DO","CURSO ESTANDARIZACIÓN","Blanco Recojo","LCK B767\n- LIM-MIA\n- LA 2480 (00:15-06:15 hrs)","PD\n- MIA-LIM\n- LA 2695 (16:20-22:00 hrs)","DO","DO","DO","DO","Inicial G3","Inicial G2","Inicial G2","LCK B767\n- LIM-BOG\n- LA 2489 (13:00-16:15 hrs)\nRecalificación B767\n- BOG-LIM\n- LA 2488 (17:20-20:45 hrs)","DO"],"nombre":"Jennifert Acurio","bp":"3779550"},{"dias":["DO","LCK A320F\nLIM-CUZ-LIM\nLA 2232 (08:35-10:05 hrs)\nLA 2233 (10:40-12:15 hrs)\nLCK A320F\nLIM-PIU-LIM\nLA 2308 (13:10-14:50 hrs)\nLA 2309 (15:25-16:55 hrs)","Inicial G13","HO FILE","DO","DO","DO","DO","TALLER 2026 - CONSTRUIR","LCK A320F\nLIM-AQP-LIM\nLA 2119 (08:40-10:10 hrs)\nLA 2118 (10:45-12:10 hrs)\nLCK A320F\nLIM-PIU-LIM\nLA 2308 (13:10-14:50 hrs)\nLA 2309 (15:25-16:55 hrs)","Inicial G3","LCK A320F\nLIM-AQP-LIM\nLA 2119 (08:40-10:10 hrs)\nLA 2118 (10:45-12:10 hrs)\nLCK A320F\nLIM-PIU-LIM\nLA 2308 (13:10-14:50 hrs)\nLA 2309 (15:25-16:55 hrs)","REUNIÓN INSTRUCTORES","DO","DO","HABILITACIÓN A320","Inicial G1","Blanco Recojo","LCK B767\n- LIM-MIA\n- LA 2480 (00:15-06:15 hrs)","Chequeo DGAC B767\n- MIA-LIM\n- LA 2481 (15:55-21:40 hrs)","DO","DO","Inicial G3","LCK A320F\nLIM-CUZ-LIM\nLA 2232 (08:35-10:05 hrs)\nLA 2233 (10:40-12:15 hrs)\nLCK A320F\nLIM-CUZ-LIM\nLA 2075 (13:25-14:50 hrs)\nLA 2076 (15:25-16:45 hrs)","Inicial G2","LCK B767\n- LIM-BOG\n- LA 2489 (13:00-16:15 hrs)\nChequeo DGAC B767\n- BOG-LIM\n- LA 2488 (17:20-20:45 hrs)","RESERVA IET\nTARDE","DO"],"nombre":"Jazmin Guerra","bp":"29530"},{"bp":"3217561","nombre":"Claudia Flores","dias":["DO","Inicial G2","LCK B767\n- LIM-MIA\n- LA 2698 (08:25-14:20 hrs)","Blanco","PD\n- MIA-LIM\n- LA 2699 (23:10-05:00 hrs)","HABILITACIÓN B787","DO","DO","TALLER 2026 - CONSTRUIR","LCK B767\n- LIM-MIA\n- LA 2698 (08:25-14:20 hrs)","Blanco","Chequeo LATAM B767\n- MIA-LIM\n- LA 2699 (23:10-05:00 hrs)","REUNIÓN INSTRUCTORES","DO","DO","Inicial G3","Situaciones de Emergencia A320F\nTripulación de Mando\nLP\n(08:30-17:30 hrs)","Inicial G1","Inicial G1","DO","DO","DO","DO","Reva de Servicio\n(08:30-17:30 hrs)\nDÍA 1","Reva de Servicio\n(08:30-17:30 hrs)\nDÍA 2","Inicial G2","HO FILE","DO"]},{"dias":["DO","AUDITORÍA\nNB\nIQT\n(Asignar vuelo)","Inicial G2","LCK A320F\nLIM-AQP-LIM\nLA 2119 (08:40-10:10 hrs)\nLA 2118 (10:45-12:10 hrs)\nLCK A320F\nLIM-CIX-LIM\nLA 2312 (13:25-14:50 hrs)\nLA 2313 (15:30-16:50 hrs)","Inicial G4","Chequeo INST. DGAC B787 \n- LIM-SCL\n- LA 2697 (09:35-13:00 hrs)\nPD\n- SCL-LIM\n- LA 2696 (16:00-19:45 hrs)","DO","DO","TALLER 2026 - CONSTRUIR","HABILITACIÓN A320","LCK A320F\nLIM-AQP-LIM\nLA 2119 (08:40-10:10 hrs)\nLA 2118 (10:45-12:10 hrs)\nLCK A320F\nLIM-PIU-LIM\nLA 2308 (13:10-14:50 hrs)\nLA 2309 (15:25-16:55 hrs)","RTI: PRÁCTICA\nA320F / B767 / B787\n(08:30-17:30 hrs)\nAPOYO TM","HO FILE","DO","DO","LCK A320F\nLIM-AQP-LIM\nLA 2119 (08:40-10:10 hrs)\nLA 2118 (10:45-12:10 hrs)\nLCK A320F\nLIM-PIU-LIM\nLA 2308 (13:10-14:50 hrs)\nLA 2309 (15:25-16:55 hrs)","Inicial G3","Inicial G1","LCK B767\n- LIM-BOG\n- LA 2489 (13:00-16:15 hrs)\nChequeo DGAC B767\n- BOG-LIM\n- LA 2488 (17:20-20:45 hrs)","DO","DO","DO","DO","Inicial G2","Inicial G2","Inicial G1","DO","DO"],"nombre":"Luis Bacigalupo","bp":"2963161"},{"dias":["VACACIONES","VACACIONES","VACACIONES","VACACIONES","VACACIONES","VACACIONES","VACACIONES","LP","LP","LP","LP","LP","LP","LP","LP","LP","LP","LP","LP","LP","LP","LP","LP","LP","LP","LP","LP","LP"],"bp":"71348","nombre":"Karla Moz"},{"dias":["VACACIONES","VACACIONES","VACACIONES","VACACIONES","VACACIONES","VACACIONES","VACACIONES","DO","TALLER 2026 - CONSTRUIR","RTI: VIRTUAL\nA320F / B767 / B787\n(08:30-17:30 hrs)\nINS TITULAR","RTI: PRÁCTICA\nA320F / B767 / B787\n(08:30-17:30 hrs)\nINS TITULAR","RTI: PRÁCTICA\nA320F / B767 / B787\n(08:30-17:30 hrs)\nINS TITULAR","Inicial G4","DO","DO","HO FILE","RTI: VIRTUAL\nA320F / B767 / B787\n(08:30-17:30 hrs)\nINS TITULAR","RTI: PRÁCTICA\nA320F / B767 / B787\n(08:30-17:30 hrs)\nINS TITULAR","RTI: PRÁCTICA\nA320F / B767 / B787\n(08:30-17:30 hrs)\nINS TITULAR","HABILITACIÓN B787","DO","DO","HABILITACIÓN B767","HABILITACIÓN B767","HABILITACIÓN B767","Reva de Servicio\n(08:30-17:30 hrs)\nDÍA 1","Reva de Servicio\n(08:30-17:30 hrs)\nDÍA 2","DO"],"nombre":"Erika Dávila","bp":"967092"},{"dias":["DO","LCK B767\n- LIM-MIA\n- LA 2698 (08:25-14:20 hrs)","PD\n- MIA-LIM\n- LA 2481 (15:55-21:40 hrs)","RESERVA IET\nTARDE","Inicial G2","Inicial G3","DO","DO","TALLER 2026 - CONSTRUIR","HO FILE","LCK ALUMNO","Inicial G1","Inicial G1","DO","DO","LCK B767\n- LIM-MIA\n- LA 2698 (08:25-14:20 hrs)","Chequeo LATAM B767\n- MIA-LIM\n- LA 2481 (15:55-21:40 hrs)","RESERVA IET\nTARDE","DO","DO","DO","DO","Blanco Recojo","LCK B767\n- LIM-MIA\n- LA 2480 (00:15-06:15 hrs)","Chequeo DGAC B767\n- MIA-LIM\n- LA 2481 (15:55-21:40 hrs)","RESERVA IET\nTARDE","Inicial G2","DO"],"bp":"2369641","nombre":"Elizabeth Torres"},{"nombre":"Patricia del Pilar Najar","bp":"2369624","dias":["DO","TTT RRVV\nALUMNO","Inicial G2","TALLER VOLUNTARIO","DO","DO","DO","DO","TALLER 2026 - CONSTRUIR","TALLER VOLUNTARIO","HO FILE","Inicial G3","Inicial G1","DO","DO","LCK B767\n- LIM-MIA\n- LA 2694 (13:30-19:30 hrs)","Blanco","PD\n- MIA-LIM\n- LA 2699 (23:10-05:00 hrs)","Inicial G1","Inicial G1","DO","DO","Inicial G4","LCK B767\n- LIM-MIA\n- LA 2698 (08:25-14:20 hrs)","Blanco","Chequeo DGAC B767\n- MIA-LIM\n- LA 2699 (23:10-05:00 hrs)","Inicial G2","DO"]},{"bp":"3134911","nombre":"Javier Zapata","dias":["DO","Inicial G13","Blanco Recojo","LCK B767\n- LIM-MIA\n- LA 2480 (00:15-06:15 hrs)","Chequeo DGAC B767\n- MIA-LIM\n- LA 2695 (16:20-22:00 hrs)","RESERVA IET\nTARDE","DO","DO","TALLER 2026 - CONSTRUIR","LCK A320F\nLIM-AQP-LIM\nLA 2123 (09:25-11:00 hrs)\nLA 2124 (11:35-13:10 hrs)\nLCK A320F\nLIM-PCL-LIM\nLA 2360 (14:05-15:20 hrs)\nLA 2361 (15:55-17:10 hrs)","Inicial G1","LCK A320F\nLIM-AQP-LIM\nLA 2123 (09:25-11:00 hrs)\nLA 2124 (11:35-13:10 hrs)\nLCK A320F\nLIM-TPP-LIM\nLA 2087 (14:10-15:35 hrs)\nLA 2088 (16:10-17:30 hrs)","LCK B767\n- LIM-BOG\n- LA 2489 (13:00-16:15 hrs)\nChequeo DGAC B767\n- BOG-LIM\n- LA 2488 (17:20-20:45 hrs)","DO","DO","Inicial G4","PD\nLIM-AQP-LIM\nLA 2119 (08:40-10:10 hrs)\nLA 2118 (10:45-12:10 hrs)\nLCK A320F\nLIM-PIU-LIM\nLA 2308 (13:10-14:50 hrs)\nLA 2309 (15:25-16:55 hrs)","Inicial G1","RTI: PRÁCTICA\nA320F / B767 / B787\n(08:30-17:30 hrs)\nAPOYO TM","Inicial G1","DO","DO","Inicial G2","HO FILE","DO","DO","DO","DO"]},{"nombre":"Jefferson Mendez","bp":"3750335","dias":["DO","HO FILE","LCK A320F\nLIM-CUZ-LIM\nLA 2232 (08:35-10:05 hrs)\nLA 2233 (10:40-12:15 hrs)\nLCK A320F\nLIM-PIU-LIM\nLA 2308 (13:10-14:50 hrs)\nLA 2309 (15:25-16:55 hrs)","Blanco Recojo","LCK B767\n- LIM-MIA\n- LA 2480 (00:15-06:15 hrs)","Chequeo DGAC B767\n- MIA-LIM\n- LA 2481 (15:55-21:40 hrs)","DO","DO","TALLER 2026 - CONSTRUIR","HABILITACIÓN A320\nASIGNAR VUELO LIM TPP\nWB","Situaciones de Emergencia B767\nTripulación de Mando\nLP\n(08:30-17:30 hrs)","LCK B767\n- LIM-BOG\n- LA 2489 (13:00-16:15 hrs)\nChequeo DGAC B767\n- BOG-LIM\n- LA 2488 (17:20-20:45 hrs)","REUNIÓN INSTRUCTORES\nTARDE","DO","DO","Ditching Presencial B767 + HANDS ON\nTripulación de Mando\nLP\n(08:30-17:30 hrs)","Inicial G1","LCK A320F\nLIM-AQP-LIM\nLA 2119 (08:40-10:10 hrs)\nLA 2118 (10:45-12:10 hrs)\nRecalificación A320F\nLIM-PIU-LIM\nLA 2308 (13:10-14:50 hrs)\nLA 2309 (15:25-16:55 hrs)","RESERVA IET","DO","DO","DO","DO","LCK A320F\nLIM-AQP-LIM\nLA 2119 (08:40-10:10 hrs)\nLA 2118 (10:45-12:10 hrs)\nPD\nLIM-PIU-LIM\nLA 2308 (13:10-14:50 hrs)\nLA 2309 (15:25-16:55 hrs)","REUNIÓN EMBAJADORES","LCK A320F\nLIM-AQP-LIM\nLA 2119 (08:40-10:10 hrs)\nLA 2118 (10:45-12:10 hrs)\nReentrenamiento A320F\nLIM-PIU-LIM\nLA 2308 (13:10-14:50 hrs)\nLA 2309 (15:25-16:55 hrs)","Inicial G2","DO"]},{"dias":["DO","Inicial G2","Inicial G1","Inicial G2","HO FILE","LCK B767\n- LIM-BOG\n- LA 2489 (13:00-16:15 hrs)\nLCK B767\n- BOG-LIM\n- LA 2488 (17:20-20:45 hrs)","DO","DO","TALLER 2026 - CONSTRUIR","Blanco Recojo","LCK B767\n- LIM-MIA\n- LA 2480 (00:15-06:15 hrs)","Habilitación B767\n- MIA-LIM\n- LA 2695 (16:20-22:00 hrs)","REUNIÓN INSTRUCTORES\nTARDE","DO","DO","Inicial G1","Reva de Servicio\n(08:30-17:30 hrs)\nDÍA 1","Reva de Servicio\n(08:30-17:30 hrs)\nDÍA 2","Inicial G2","DO","DO","DO","DO","Blanco Recojo","LCK B767\n- LIM-MIA\n- LA 2480 (00:15-06:15 hrs)","PD\n- MIA-LIM\n- LA 2695 (16:20-22:00 hrs)","RESERVA IET\nTARDE","DO"],"bp":"3852423","nombre":"Gabriela Ungaro"},{"bp":"2604360","nombre":"Mariella Carrasco","dias":["DO","HO FILE","Inicial G1","Inicial G13","LCK B767\n- LIM-BOG\n- LA 2489 (13:00-16:15 hrs)\nChequeo DGAC B767\n- BOG-LIM\n- LA 2488 (17:20-20:45 hrs)","DO","DO","VACACIONES","VACACIONES","VACACIONES","VACACIONES","VACACIONES","VACACIONES","VACACIONES","VACACIONES","VACACIONES","VACACIONES","Ditching Presencial A320F + HANDS ON\nTripulación de Mando\nLP\n(08:30-17:30 hrs)","Reva de Servicio\n(08:30-17:30 hrs)\nDÍA 1","Reva de Servicio\n(08:30-17:30 hrs)\nDÍA 2","DO","DO","Inicial G2","RTI: VIRTUAL\nA320F / B767\n(08:30-17:30 hrs)\nINS CRM","Blanco Recojo","LCK B767\n- LIM-MIA\n- LA 2480 (00:15-06:15 hrs)","Chequeo DGAC B767\n- MIA-LIM\n- LA 2481 (15:55-21:40 hrs)","DO"]},{"nombre":"Cesar Campos","dias":["DO","TTT RRVV\nINS","RTI: VIRTUAL\nA320F / B767 / B787\n(08:30-17:30 hrs)\nINS CRM","Inicial G2","RTI: PRÁCTICA\nA320F / B767 / B787\n(08:30-17:30 hrs)\nINS APOYO","Inicial G2","DO","DO","TALLER 2026 - CONSTRUIR","Inicial G4","Inicial G1","Reva de Servicio\n(08:30-17:30 hrs)\nDÍA 1","Reva de Servicio\n(08:30-17:30 hrs)\nDÍA 2","DO","DO","Inicial G1","HABILITACIÓN A320","Inicial G2","HO FILE","DO","DO","DO","DO","Inicial G2","RTI: VIRTUAL\nA320F / B767\n(08:30-17:30 hrs)\nINS CRM","DESAYUNO SAB\nMT","RTI: PRÁCTICA\nA320F / B767\n(08:30-17:30 hrs)\nINS APOYO","DO"],"bp":"2823133"},{"dias":["DO","Inicial G1","Reva de Servicio\n(08:30-17:30 hrs)\nDÍA 1","Reva de Servicio\n(08:30-17:30 hrs)\nDÍA 2","Inicial G2","HO FILE","DO","DO","TALLER 2026 - CONSTRUIR","RTI: VIRTUAL\nA320F / B767 / B787\n(08:30-17:30 hrs)\nINS CRM","Inicial G1","RTI: PRÁCTICA\nA320F / B767 / B787\n(08:30-17:30 hrs)\nINS APOYO","Inicial G1","DO","DO","Chequeo LATAM y Reentrenamiento B767\n- LIM-MIA\n- LA 2698 (08:25-14:20 hrs)","Reentrenamiento B767\n- MIA-LIM\n- LA 2481 (15:55-21:40 hrs)","RESERVA IET\nTARDE","Inicial G2","DO","DO","DO","DO","RTI: VIRTUAL\nA320F / B767\n(08:30-17:30 hrs)\nINS TITULAR","REUNIÓN EMBAJADORES","Inicial G4","Inicial G3","DO"],"nombre":"Kevin Segovia","bp":"3189967"},{"dias":["DO","Inicial G1","DITCHING TM\nTC","HO FILE","DO","DO","DO","DO","TALLER 2026 - CONSTRUIR","Reva de Servicio\n(08:30-17:30 hrs)\nDÍA 1","Reva de Servicio\n(08:30-17:30 hrs)\nDÍA 2","Inicial G1","Curso HB6","DO","DO","Inicial G1","RTI: VIRTUAL\nA320F / B767 / B787\n(08:30-17:30 hrs)\nINS CRM","Inicial G2","RTI: PRÁCTICA\nA320F / B767 / B787\n(08:30-17:30 hrs)\nINS APOYO","Inicial G2","DO","DO","Chequeo LATAM B767\n- LIM-MIA\n- LA 2698 (08:25-14:20 hrs)","Chequeo LATAM B767\n- MIA-LIM\n- LA 2481 (15:55-21:40 hrs)","RESERVA IET\nTARDE","RTI: PRÁCTICA\nA320F / B767\n(08:30-17:30 hrs)\nINS APOYO","Inicial G1","DO"],"bp":"2415373","nombre":"Milagros Salas"},{"dias":["VACACIONES","VACACIONES","VACACIONES","VACACIONES","VACACIONES","VACACIONES","VACACIONES","VACACIONES","VACACIONES","VACACIONES","VACACIONES","VACACIONES","VACACIONES","VACACIONES","DO","HABILITACIÓN B767","HABILITACIÓN B767","HABILITACIÓN B767","HABILITACIÓN A320","Inicial G2","DO","DO","Inicial G2","HO FILE","Inicial G1","RTI: PRÁCTICA\nA320F / B767\n(08:30-17:30 hrs)\nINS TITULAR","RESERVA IET","DO"],"nombre":"Judith Fernandez","bp":"2440915"},{"dias":["SICK","SICK","SICK","SICK","SICK","SICK","SICK","SICK","SICK","SICK","SICK","SICK","SICK","SICK","SICK","SICK","SICK","SICK","SICK","SICK","SICK","SICK","SICK","SICK","SICK","SICK","SICK","SICK"],"bp":"3796947","nombre":"Rafael Nieto"},{"nombre":"Gianfranco Celiz","dias":["DO","Chequeo LATAM B767\n- LIM-MIA\n- LA 2698 (08:25-14:20 hrs)","Chequeo LATAM B767\n- MIA-LIM\n- LA 2481 (15:55-21:40 hrs)","RESERVA IET\nTARDE","Reva de Servicio\n(08:30-17:30 hrs)\nDÍA 1","Reva de Servicio\n(08:30-17:30 hrs)\nDÍA 2","DO","DO","TALLER 2026 - CONSTRUIR","Inicial G3","Curso HB6","Curso HB6","Curso HB6","DO","DO","HABILITACIÓN B767","HABILITACIÓN B767","HABILITACIÓN B767","DESAYUNO SAB\nMT","HO FILE","DO","DO","DO","DO","RTI: VIRTUAL\nA320F / B767\n(08:30-17:30 hrs)\nINS TITULAR","Inicial G3","RTI: PRÁCTICA\nA320F / B767\n(08:30-17:30 hrs)\nINS TITULAR","DO"],"bp":"3841387"}],"mes":"2026-02","hoja":"FEBRERO","fuente":"10 - Rol_Instructores_LP_OCTUBRE_1.xlsx"} | C3: 46296.54
A4: 2026-03 | B4: {"hoja":"MARZO","mes":"2026-03","instructores":[{"nombre":"Fiorella Ruiz","bp":"2713993","dias":["FDS","HO FILE","PD\n- LIM-ATL\n- LA 2482 (12:15-19:35 hrs)","Blanco","LCK B767\n- ATL-LIM\n- LA 2483 (22:15-05:00 hrs)","RENOVACIÓN INS A320F\nLIM-PIU-LIM\nLA 2306 (09:35-11:20 hrs)\nLA 2307 (11:55-13:25 hrs)","FDS","FDS","PREPARACIÓN\nAUDITORÍA\nPRE IOSA","PREPARACIÓN\nAUDITORÍA\nPRE IOSA","DO","RECURRENTE AUDITOR 2026","RECURRENTE AUDITOR 2026","RECURRENTE AUDITOR 2026","FDS","HANDS ON B767","RESERVA IET","Reentrenamiento B767\n- LIM-MIA\n- LA 2694 (13:30-19:25 hrs)","LCK B767\n- MIA-LIM\n- LA 2695 (16:55-22:40 hrs)","RESERVA IET\nTARDE","FDS","FDS","VACACIONES","VACACIONES","VACACIONES","VACACIONES","VACACIONES","FDS","FDS","TTT REVA DE SERVICIOS","TTT REVA DE SERVICIOS"]},{"nombre":"Sebastian Correa","dias":["FDS","LCK B767\n- LIM-MIA\n- LA 2698 (08:25-14:20 hrs)","Habilitación B767\n- MIA-LIM\n- LA 2695 (16:45-22:40 hrs)","RESERVA IET\nTARDE","Recalificación A320F\nLIM-CUZ-LIM\nLA 2232 (08:35-10:05 hrs)\nLA 2233 (10:40-12:15 hrs)\nLCK A320F\nLIM-PIU-LIM\nLA 2308 (13:10-14:50 hrs)\nLA 2309 (15:25-16:55 hrs)","RESERVA IET","FDS","FDS","CUMP","LCK A320F\nLIM-CUZ-LIM\nLA 2232 (08:35-10:05 hrs)\nLA 2233 (10:40-12:15 hrs)\nLCK A320F\nLIM-PIU-LIM\nLA 2308 (13:10-14:50 hrs)\nLA 2309 (15:25-16:55 hrs)","Reva de Servicio\n(08:30-17:30 hrs)\nDÍA 1","Reva de Servicio\n(08:30-17:30 hrs)\nDÍA 2","REUNIÓN INSTRUCTORES","FDS","FDS","HO FILE","LCK A320F\nLIM-CUZ-LIM\nLA 2232 (08:35-10:05 hrs)\nLA 2233 (10:40-12:15 hrs)\nLCK A320F\nLIM-PIU-LIM\nLA 2308 (13:10-14:50 hrs)\nLA 2309 (15:25-16:55 hrs)","HANDS ON B767","Reentrenamiento A320F\nLIM-CUZ-LIM\nLA 2266 (11:15-12:40 hrs)\nLA 2267 (13:15-14:50 hrs)","LCK A320F\nLIM-CUZ-LIM\nLA 2232 (08:35-10:05 hrs)\nLA 2233 (10:40-12:15 hrs)\nLCK A320F\nLIM-PIU-LIM\nLA 2308 (13:10-14:50 hrs)\nLA 2309 (15:25-16:55 hrs)","FDS","FDS","PD\n- LIM-ATL\n- LA 2482 (12:15-19:35 hrs)","Blanco","LCK B767\n- ATL-LIM\n- LA 2483 (22:15-05:00 hrs)","RTI: PRÁCTICA\nA320F / B767 / B787\n(08:30-17:30 hrs)\nINS APOYO","Inicial G3","FDS","FDS","Inicial G3","Inicial G3"],"bp":"2396710"},{"dias":["VACACIONES","HO FILE","LCK A320F\nLIM-CUZ-LIM\nLA 2232 (08:35-10:05 hrs)\nLA 2233 (10:40-12:15 hrs)\nLCK A320F\nLIM-PIU-LIM\nLA 2308 (13:10-14:50 hrs)\nLA 2309 (15:25-16:55 hrs)","RESERVA IET","Reva de Servicio\n(08:30-17:30 hrs)\nDÍA 1","Reva de Servicio\n(08:30-17:30 hrs)\nDÍA 2","FDS","FDS","LCK A320F\nLIM-AQP-LIM\nLA 2123 (09:20-11:00 hrs)\nLA 2124 (11:35-13:10 hrs)\nLCK A320F\nLIM-TPP-LIM\nLA 2087 (14:10-15:35 hrs)\nLA 2088 (16:10-17:30 hrs)","Reva de Servicio\n(08:30-17:30 hrs)\nDÍA 1","Reva de Servicio\n(08:30-17:30 hrs)\nDÍA 2","LCK A320F\nLIM-AQP-LIM\nLA 2123 (09:20-11:00 hrs)\nLA 2124 (11:35-13:10 hrs)\nLCK A320F\nLIM-TPP-LIM\nLA 2087 (14:10-15:35 hrs)\nLA 2088 (16:10-17:30 hrs)","REUNIÓN INSTRUCTORES","FDS","FDS","LCK A320F\nLIM-CUZ-LIM\nLA 2232 (08:35-10:05 hrs)\nLA 2233 (10:40-12:15 hrs)\nLCK A320F\nLIM-CIX-LIM\nLA 2312 (13:25-14:50 hrs)\nLA 2313 (15:25-16:45 hrs)","Reva de Servicio\n(08:30-17:30 hrs)\nDÍA 1","Reva de Servicio\n(08:30-17:30 hrs)\nDÍA 2","HANDS ON B767","LCK B787\n- LIM-SCL\n- LA 2697 (09:35-13:00 hrs)\nLCK B787\n- SCL-LIM\n- LA 2696 (16:00-19:45 hrs)","FDS","FDS","HO FILE","LCK A320F\nLIM-CUZ-LIM\nLA 2232 (08:35-10:05 hrs)\nLA 2233 (10:40-12:15 hrs)\nLCK A320F\nLIM-PIU-LIM\nLA 2308 (13:10-14:50 hrs)\nLA 2309 (15:25-16:55 hrs)","Inicial G3","Inicial G3","LCK A320F\nLIM-CUZ-LIM\nLA 2537 (09:15-10:50 hrs)\nLA 2008 (11:25-12:55 hrs)\nLCK A320F\nLIM-AQP-LIM\nLA 2115 (13:55-15:25 hrs)\nLA 2114 (16:00-17:35 hrs)","FDS","FDS","PD\n- LIM-ATL\n- LA 2482 (12:15-19:35 hrs)","Blanco"],"bp":"1271571","nombre":"Christian Rondon"},{"bp":"2843319","dias":["DO","HO FILE","RESERVA IET","HANDS ON B767","HABILITACIÓN B787","RESERVA IET\nTARDE","DO","DO","PREPARACIÓN\nAUDITORÍA\nPRE IOSA","PD\n- LIM-ATL\n- LA 2482 (12:15-19:35 hrs)","Blanco","LCK B767\n- ATL-LIM\n- LA 2483 (22:15-05:00 hrs)","REUNIÓN INSTRUCTORES","DO","DO","DO","DO","LCK ALUMNO","LCK ALUMNO","RESERVA IET\nTARDE","DO","DO","HANDS ON B767","Reva de Servicio\n(08:30-17:30 hrs)\nDÍA 1","Reva de Servicio\n(08:30-17:30 hrs)\nDÍA 2","Inicial G3","Inicial G3","DO","DO","TTT REVA DE SERVICIOS","TTT REVA DE SERVICIOS"],"nombre":"Karen Santa Cruz"},{"nombre":"Jennifert Acurio","dias":["DO","HO FILE","Reva de Servicio\n(08:30-17:30 hrs)\nDÍA 1","Reva de Servicio\n(08:30-17:30 hrs)\nDÍA 2","HANDS ON B767","DO","DO","DO","DO","LCK B767\n- LIM-MIA\n- LA 2698 (08:25-14:20 hrs)","PD\n- MIA-LIM\n- LA 2481 (15:55-21:40 hrs)","RESERVA IET\nTARDE","REUNIÓN INSTRUCTORES","DO","DO","Reentrenamiento A320F\nLIM-AQP-LIM\nLA 2109 (10:30-12:00 hrs)\nLA 2108 (12:40-14:15 hrs)","RESERVA IET","Habilitación B767\n- LIM-ATL\n- LA 2482 (12:15-19:35 hrs)","Blanco","LCK B767\n- ATL-LIM\n- LA 2483 (22:15-05:00 hrs)","DO","DO","LCK A320F\nLIM-CUZ-LIM\nLA 2232 (08:35-10:05 hrs)\nLA 2233 (10:40-12:15 hrs)\nLCK A320F\nLIM-CIX-LIM\nLA 2312 (13:25-14:50 hrs)\nLA 2313 (15:25-16:45 hrs)","Inicial G5","HANDS ON B767","LCK A320F\nLIM-CUZ-LIM\nLA 2232 (08:35-10:05 hrs)\nLA 2233 (10:40-12:15 hrs)\nLCK A320F\nLIM-CIX-LIM\nLA 2312 (13:25-14:50 hrs)\nLA 2313 (15:30-16:50 hrs)","RESERVA IET","DO","DO","HANDS ON B767","LCK B767\n- LIM-MIA\n- LA 2698 (08:15-14:20 hrs)"],"bp":"3779550"},{"dias":["DO","PD\n- LIM-MIA\n- LA 2694 (13:30-19:25 hrs)","Blanco","LCK B767\n- MIA-LIM\n- LA 2699 (23:10-05:00 hrs)","RTI: PRÁCTICA\nA320F / B767\n(08:30-17:30 hrs)\nINS APOYO TM","DO","DO","DO","DO","Inicial G2","LCK A320F\nLIM-CUZ-LIM\nLA 2232 (08:35-10:05 hrs)\nLA 2233 (10:40-12:15 hrs)\nLCK A320F\nLIM-PIU-LIM\nLA 2308 (13:10-14:50 hrs)\nLA 2309 (15:25-16:55 hrs)","Curso 50%","Inicial G4","DO","DO","LCK A320F\nLIM-AQP-LIM\nLA 2123 (09:20-11:00 hrs)\nLA 2124 (11:35-13:10 hrs)\nLCK A320F\nLIM-CUZ-LIM\nLA 2075 (14:25-15:55 hrs)\nLA 2076 (16:30-18:00 hrs)","HO FILE","LCK A320F\nLIM-CUZ-LIM\nLA 2232 (08:35-10:05 hrs)\nLA 2233 (10:40-12:15 hrs)\nLCK A320F\nLIM-CIX-LIM\nLA 2312 (13:25-14:50 hrs)\nLA 2313 (15:30-16:50 hrs)","Reva de Servicio\n(08:30-17:30 hrs)\nDÍA 1","Reva de Servicio\n(08:30-17:30 hrs)\nDÍA 2","DO","DO","LCK A320F\nLIM-AQP-LIM\nLA 2123 (09:20-11:00 hrs)\nLA 2124 (11:35-13:10 hrs)\nLCK A320F\nLIM-TPP-LIM\nLA 2087 (14:10-15:35 hrs)\nLA 2088 (16:10-17:30 hrs)","REU EMBAJADORES","PD\n- LIM-MIA\n- LA 2694 (13:30-19:25 hrs)","LCK B767\n- MIA-LIM\n- LA 2695 (16:55-22:40 hrs)","RESERVA IET\nTARDE","DO","DO","HABILITACIÓN B787","RESERVA IET\nTARDE"],"bp":"29530","nombre":"Jazmin Guerra"},{"bp":"3217561","nombre":"Claudia Flores","dias":["DO","Curso 50%","Curso 50%","Curso 50%","Curso 50%","Curso 50%","DO","DO","LCK B767\n- LIM-MIA\n- LA 2698 (08:25-14:20 hrs)","PD\n- MIA-LIM\n- LA 2695 (16:55-22:40 hrs)","RESERVA IET\nTARDE","DO","DO","DO","DO","PD\n- LIM-ATL\n- LA 2482 (12:15-19:35 hrs)","Blanco","LCK B767\n- ATL-LIM\n- LA 2483 (22:15-05:00 hrs)","PREPARACIÓN\nAUDITORÍA\nPRE IOSA","PREPARACIÓN\nAUDITORÍA\nPRE IOSA","DO","DO","HO FILE","REU EMBAJADORES","Inicial G3","Inicial G3","Inicial G4","DO","DO","Inicial G3","Inicial G3"]},{"dias":["VACACIONES","VACACIONES","VACACIONES","VACACIONES","VACACIONES","VACACIONES","VACACIONES","DO","HABILITACIÓN B787","RESERVA IET\nTARDE","Reentrenamiento B767\n- LIM-MIA\n- LA 2694 (13:30-19:25 hrs)","LCK B767\n- MIA-LIM\n- LA 2695 (16:55-22:40 hrs)","REUNIÓN INSTRUCTORES\nTARDE","DO","DO","PD\n- LIM-MIA\n- LA 2694 (13:30-19:25 hrs)","Blanco","LCK B767\n- MIA-LIM\n- LA 2699 (23:10-05:00 hrs)","PREPARACIÓN\nAUDITORÍA\nPRE IOSA","PREPARACIÓN\nAUDITORÍA\nPRE IOSA","DO","DO","HO FILE","PD\n- LIM-ATL\n- LA 2482 (12:15-19:35 hrs)","Blanco","LCK B767\n- ATL-LIM\n- LA 2483 (22:15-05:00 hrs)","Inicial G3","DO","DO","CRM REFRESCO IDE","RESERVA IET"],"bp":"2963161","nombre":"Luis Bacigalupo"},{"bp":"71348","dias":["LP","LP","LP","LP","LP","LP","LP","LP","LP","LP","LP","LP","LP","LP","LP","LP","LP","LP","LP","LP","LP","LP","LP","LP","LP","LP","LP","LP","LP","LP","LP"],"nombre":"Karla Moz"},{"bp":"967092","nombre":"Erika Dávila","dias":["DO","HABILITACIÓN A320F","HO FILE","Inicial G4","Inicial G4","RESERVA IET","DO","DO","HANDS ON B787","Curso 50%","Inicial G4","RTI: PRÁCTICA\nA320F / B767\n(08:30-17:30 hrs)\nINS APOYO TM","REUNIÓN INSTRUCTORES","DO","DO","TALLER VOLUNTARIO DE SEGURIDAD","HANDS ON B787","HANDS ON B787","RTI: PRÁCTICA\nA320F / B767\n(08:30-17:30 hrs)\nINS APOYO TM","RTI: PRÁCTICA\nA320F / B767\n(08:30-17:30 hrs)\nINS APOYO TM","DO","DO","Inicial G4","RTI: VIRTUAL\nA320F / B767 / B787\n(08:30-17:30 hrs)","RTI: PRÁCTICA\nA320F / B767 / B787\n(08:30-17:30 hrs)","RTI: PRÁCTICA\nA320F / B767 / B787\n(08:30-17:30 hrs)","DO","DO","DO","DO","HANDS ON B767"]},{"nombre":"Elizabeth Torres","dias":["DO","HO FILE","RESERVA IET","LCK A320F\nLIM-CUZ-LIM\nLA 2232 (08:35-10:05 hrs)\nLA 2233 (10:40-12:15 hrs)\nLCK A320F\nLIM-CIX-LIM\nLA 2312 (13:25-14:50 hrs)\nLA 2313 (15:30-16:50 hrs)","Inicial G3","Inicial G4","DO","DO","Inicial G4","Inicial G4","PD\n- LIM-ATL\n- LA 2482 (12:15-19:35 hrs)","Blanco","LCK B767\n- ATL-LIM\n- LA 2483 (22:15-05:00 hrs)","DO","DO","CRM REFRESCO IDE","RESERVA IET","Inicial G5","Inicial G4","Inicial G4","DO","DO","Inicial G5","Inicial G4","Inicial G3","Recalificación A320F\nLIM-PIU-LIM\nLA 2306 (09:35-11:20 hrs)\nLA 2307 (11:55-13:25 hrs)","DO","DO","DO","DO","Reva de Servicio\n(08:30-17:30 hrs)\nDÍA 1"],"bp":"2369641"},{"nombre":"Patricia Najar","bp":"2369624","dias":["DO","HO FILE","Inicial G4","PD\n- LIM-ATL\n- LA 2482 (12:15-19:35 hrs)","Blanco","LCK B767\n- ATL-LIM\n- LA 2483 (22:15-05:00 hrs)","DO","DO","PREPARACIÓN\nAUDITORÍA\nPRE IOSA","PREPARACIÓN\nAUDITORÍA\nPRE IOSA","DO","RECURRENTE AUDITOR 2026","RECURRENTE AUDITOR 2026","RECURRENTE AUDITOR 2026","DO","CRM REFRESCO IDE","LCK A320F\nLIM-AQP-LIM\nLA 2123 (09:20-11:00 hrs)\nLA 2124 (11:35-13:10 hrs)\nLCK A320F\nLIM-PCL-LIM\nLA 2360 (14:05-15:20 hrs)\nLA 2361 (16:00-17:10 hrs)","Inicial G4","LCK A320F\nLIM-TCQ-LIM\nLA 2245 (09:00-10:50 hrs)\nLA 2244 (11:25-13:15 hrs)\nLCK A320F\nLIM-TPP-LIM\nLA 2087 (14:10-15:35 hrs)\nLA 2088 (16:10-17:30 hrs)","HABILITACIÓN A320F","DO","DO","LCK B767\n- LIM-MIA\n- LA 2698 (08:25-14:20 hrs)","Recalificación B767\n- MIA-LIM\n- LA 2695 (16:55-22:40 hrs)","RESERVA IET\nTARDE","DO","DO","DO","DO","Inicial G5","RESERVA IET"]},{"dias":["VACACIONES","VACACIONES","VACACIONES","VACACIONES","VACACIONES","VACACIONES","VACACIONES","VACACIONES","VACACIONES","VACACIONES","VACACIONES","VACACIONES","VACACIONES","VACACIONES","VACACIONES","VACACIONES","VACACIONES","VACACIONES","VACACIONES","VACACIONES","VACACIONES","VACACIONES","VACACIONES","HABILITACIÓN A320F","PD\n- LIM-ATL\n- LA 2482 (12:15-19:35 hrs)","Blanco","LCK B767\n- ATL-LIM\n- LA 2483 (22:15-05:00 hrs)","DO","DO","LCK B767\n- LIM-MIA\n- LA 2698 (08:15-14:20 hrs)","PD\n- MIA-LIM\n- LA 2695 (16:10-22:00 hrs)"],"nombre":"Javier Zapata","bp":"3134911"},{"dias":["DO","PD\n- LIM-ATL\n- LA 2482 (12:15-19:35 hrs)","Blanco","LCK B767\n- ATL-LIM\n- LA 2483 (22:15-05:00 hrs)","Inicial G3","HANDS ON B767","DO","DO","PD\n- LIM-MIA\n- LA 2694 (13:30-19:25 hrs)","Blanco","LCK B767\n- MIA-LIM\n- LA 2699 (23:10-05:00 hrs)","DESAYUNO SAB","REUNIÓN INSTRUCTORES","DO","DO","LCK B767\n- LIM-MIA\n- LA 2698 (08:25-14:20 hrs)","Reentrenamiento B767\n- MIA-LIM\n- LA 2695 (16:55-22:40 hrs)","RESERVA IET\nTARDE","DO","DO","DO","DO","HO FILE","CUMP","CUMP","Inicial G4","Inicial G4","DO","DO","CRM REFRESCO IDE","RESERVA IET"],"bp":"3750335","nombre":"Jefferson Mendez"},{"nombre":"Gabriela Ungaro","bp":"3852423","dias":["DO","Inicial G4","LCK B767\n- LIM-MIA\n- LA 2698 (08:25-14:20 hrs)","Chequeo DGAC\n- MIA-LIM\n- LA 2481 (15:55-21:40 hrs)","RESERVA IET\nTARDE","LCK A320F\nLIM-CUZ-LIM\nLA 2232 (08:35-10:05 hrs)\nLA 2233 (10:40-12:15 hrs)\nLCK A320F\nLIM-PIU-LIM\nLA 2308 (13:10-14:50 hrs)\nLA 2309 (15:25-16:55 hrs)","DO","DO","PD\n- LIM-ATL\n- LA 2482 (12:15-19:35 hrs)","Blanco","LCK B767\n- ATL-LIM\n- LA 2483 (22:15-05:00 hrs)","LCK A320F\nLIM-CUZ-LIM\nLA 2232 (08:35-10:05 hrs)\nLA 2233 (10:40-12:15 hrs)\nLCK A320F\nLIM-PIU-LIM\nLA 2308 (13:10-14:50 hrs)\nLA 2309 (15:25-16:55 hrs)","REUNIÓN INSTRUCTORES","DO","DO","HO FILE","LCK B767\n- LIM-MIA\n- LA 2698 (08:25-14:20 hrs)","Chequeo DGAC\n- MIA-LIM\n- LA 2481 (15:55-21:40 hrs)","RESERVA IET\nTARDE","HABILITACIÓN A320F","DO","DO","RESERVA IET","VACACIONES","VACACIONES","VACACIONES","VACACIONES","VACACIONES","VACACIONES","VACACIONES","VACACIONES"]},{"dias":["DO","Inicial G3","Inicial G3","PD\n- LIM-MIA\n- LA 2694 (13:30-19:25 hrs)","LCK B767\n- MIA-LIM\n- LA 2695 (16:55-22:40 hrs)","RESERVA IET\nTARDE","DO","DO","PREPARACIÓN\nAUDITORÍA\nPRE IOSA","PREPARACIÓN\nAUDITORÍA\nPRE IOSA","DO","RECURRENTE AUDITOR 2026","RECURRENTE AUDITOR 2026","RECURRENTE AUDITOR 2026","DO","HO FILE","PD\n- LIM-ATL\n- LA 2482 (12:15-19:35 hrs)","Blanco","LCK B767\n- ATL-LIM\n- LA 2483 (22:15-05:00 hrs)","Inicial G3","DO","DO","TALLER VOLUNTARIO DE SEGURIDAD","LCK B767\n- LIM-MIA\n- LA 2698 (08:25-14:20 hrs)","Chequeo DGAC\n- MIA-LIM\n- LA 2481 (15:55-21:40 hrs)","RESERVA IET\nTARDE","DO","DO","DO","DO","HAB A320F"],"nombre":"Mariella Carrasco","bp":"2604360"},{"dias":["DO","Inicial G3","RTI: VIRTUAL\nA320F / B767\n(08:30-17:30 hrs)\nINS TITULAR","Inicial G3","RTI: PRÁCTICA\nA320F / B767\n(08:30-17:30 hrs)\nINS TITULAR","Inicial G3","DO","DO","Inicial G3","RTI: VIRTUAL\nA320F / B767\n(08:30-17:30 hrs)\nINS TITULAR","Curso 50%","RTI: PRÁCTICA\nA320F / B767\n(08:30-17:30 hrs)\nINS TITULAR","REUNIÓN INSTRUCTORES","DO","DO","HO FILE","RTI: VIRTUAL\nA320F / B767\n(08:30-17:30 hrs)\nINS TITULAR","Inicial G3","RTI: PRÁCTICA\nA320F / B767\n(08:30-17:30 hrs)\nINS TITULAR","Inicial G3","DO","DO","Inicial G3","Inicial G3","HANDS ON B767 \nALUMNO","DO","DO","DO","DO","LCK ALUMNO","LCK ALUMNO"],"bp":"2823133","nombre":"Cesar Campos"},{"dias":["DO","Inicial G2","RTI: VIRTUAL\nA320F / B767\n(08:30-17:30 hrs)\nINS CRM","Inicial G3","RTI: PRÁCTICA\nA320F / B767\n(08:30-17:30 hrs)\nINS APOYO","Inicial G3","DO","DO","Inicial G3","RTI: VIRTUAL\nA320F / B767\n(08:30-17:30 hrs)\nINS CRM","HO FILE","RTI: PRÁCTICA\nA320F / B767\n(08:30-17:30 hrs)\nINS APOYO","REUNIÓN INSTRUCTORES","DO","DO","HANDS ON B767 \nALUMNO","RTI: VIRTUAL\nA320F / B767\n(08:30-17:30 hrs)\nINS CRM","Inicial G3","RTI: PRÁCTICA\nA320F / B767\n(08:30-17:30 hrs)\nINS APOYO","Inicial G3","DO","DO","Inicial G3","LCK ALUMNO","LCK ALUMNO","RESERVA IET\nTARDE","DO","DO","DO","DO","HAB A320F"],"nombre":"Kevin Segovia","bp":"3189967"},{"nombre":"Milagros Salas","dias":["DO","HO FILE","Inicial G2","Inicial G1","DO","DO","DO","DO","Inicial G2","Inicial G3","RESERVA IET","HABILITACIÓN A320F","REUNIÓN INSTRUCTORES","DO","DO","TALLER VOLUNTARIO DE SEGURIDAD","Inicial G5","RTI: VIRTUAL\nA320F / B767\n(08:30-17:30 hrs)\nINS TITULAR","Inicial G3","RTI: PRÁCTICA\nA320F / B767\n(08:30-17:30 hrs)\nINS TITULAR","DO","DO","Inicial G3","Inicial G3","Inicial G5","Inicial G5","Inicial G5","DO","DO","Inicial G4","Inicial G4"],"bp":"2415373"},{"dias":["DO","HO FILE","Inicial G1","Inicial G2","Inicial G1","Inicial G2","DO","DO","LCK ALUMNO","LCK ALUMNO","LCK ALUMNO","Reva de Servicio\n(08:30-17:30 hrs)\nDÍA 1","Reva de Servicio\n(08:30-17:30 hrs)\nDÍA 2","DO","DO","Inicial G5","Inicial G4","RTI: VIRTUAL\nA320F / B767\n(08:30-17:30 hrs)\nINS CRM","Inicial G3","RTI: PRÁCTICA\nA320F / B767\n(08:30-17:30 hrs)\nINS APOYO","DO","DO","TALLER VOLUNTARIO DE SEGURIDAD","Inicial G3","Reva de Servicio\n(08:30-17:30 hrs)\nDÍA 1","Reva de Servicio\n(08:30-17:30 hrs)\nDÍA 2","DO","DO","DO","DO","Inicial G5"],"bp":"2440915","nombre":"Judith Fernandez"},{"dias":["SICK","SICK","SICK","SICK","SICK","SICK","SICK","SICK","SICK","SICK","SICK","SICK","SICK","SICK","SICK","SICK","SICK","SICK","SICK","SICK","SICK","SICK","SICK","SICK","SICK","SICK","SICK","SICK","SICK","SICK","SICK"],"nombre":"Rafael Nieto","bp":"3796947"},{"dias":["DO","Inicial G1","Inicial G3","RESERVA IET","Inicial G2","Inicial G1","DO","DO","Curso 50%","Inicial G3","HANDS ON B767","HABILITACIÓN A320F","REUNIÓN INSTRUCTORES","DO","DO","Inicial G4","HO FILE","Inicial G3","Inicial G3","DO","DO","DO","DO","RTI: VIRTUAL\nA320F / B767 / B787\n(08:30-17:30 hrs)\nINS CRM","RTI: PRÁCTICA\nA320F / B767 / B787\n(08:30-17:30 hrs)\nINS APOYO","Reva de Servicio\n(08:30-17:30 hrs)\nDÍA 1","Reva de Servicio\n(08:30-17:30 hrs)\nDÍA 2","DO","DO","Inicial G4","Inicial G4"],"bp":"3841387","nombre":"Gianfranco Celiz"}],"fuente":"10 - Rol_Instructores_LP_OCTUBRE_1.xlsx"} | C4: 46296.54
