Workbook

Sheet Instrucciones
A1: Base de usuarios del Rol de Instructores LP
A3: Usuarios | B3: Una fila por persona. Para agregar a alguien, escribe una fila nueva debajo de la última. Las celdas amarillas de la columna Correo corporativo están por completar.
A4: Rol | B4: Instructor o Administrador. Se elige de la lista.
A5: Activo | B5: SI o NO. Para dar de baja a alguien, cambia a NO en lugar de borrar la fila, así se conserva su historial.
A6: Registro | B6: Lo llena la aplicación en cada ingreso, salida o intento fallido. No hace falta editarla a mano.
A7: Ultimo_Acceso | B7: Se calcula sola desde Usuarios y Registro. No escribir aquí.
A8: Permisos | B8: Qué vistas ve cada rol. SI muestra la vista y NO la oculta.
A10: Ejemplo de fila en Usuarios | B10: BP 1234567 | Nombre Apellido | APELLIDO APELLIDO NOMBRE | nombre.apellido@latam.com | Instructor | A319/A320/A321/B767 | JSB | INS | SI
A11: Ejemplo de fila en Registro | B11: 27/09/2026 08:15:00 | 1234567 | Nombre Apellido | nombre.apellido@latam.com | Instructor | Ingreso | OK | Chrome en Windows
A12: Fuentes | B12: Un Google Sheet por mes (hoja ROL INS). Se agregan desde la app (Actualizar rol › Conectar Google Sheet) o escribiendo Mes (aaaa-mm) y el enlace. Activo = NO pausa la lectura.
A13: Solicitudes | B13: Pedidos de jefatura e instructores: BP, Nombre, Desde, Hasta, Tipo y Estado (asignado / no se asignó).
A14: Vigencias | B14: Experiencia reciente por BP (hoja BG INS). Escribe VENCIDO en la columna programada para generar una alerta.
A15: Acceso a la app | B15: Usuario = BP o correo corporativo. La primera vez, coordinación genera un código temporal (Usuarios y accesos) y la persona crea su contraseña. Las contraseñas no se guardan en este archivo.
... A23: Perfiles | B23: Perfiles de acceso de coordinación: por sección, Sin acceso, Ver o Gestionar. Se asignan en la columna Perfil de Usuarios (vacío = Coordinación completa). Se editan desde la app en Usuarios y accesos. La hoja Permisos aplica solo a instructores.

Sheet Perfiles
A1: Perfil | B1: Descripción | C1: Indicadores | D1: Seguimiento del mes | E1: Rol completo | F1: Equipo por día | G1: Por instructor | H1: Vacaciones | I1: Intercambios | J1: Actualizar rol | K1: Tipos y colores | L1: Usuarios y accesos
A2: Coordinación completa | B2: Ve y gestiona todo el panel de coordinación. | C2: Gestionar | D2: Gestionar | E2: Gestionar | F2: Gestionar | G2: Gestionar | H2: Gestionar | I2: Gestionar | J2: Gestionar | K2: Gestionar | L2: Gestionar
A3: Solo lectura | B3: Ve el panel completo sin poder aprobar, editar ni cambiar accesos. | C3: Ver | D3: Ver | E3: Ver | F3: Ver | G3: Ver | H3: Ver | I3: Ver | J3: Sin acceso | K3: Ver | L3: Sin acceso

Sheet Intercambios
A1: ID | B1: Mes | C1: Días | D1: Solicitante BP | E1: Solicitante | F1: Receptor BP | G1: Receptor | H1: Actividades solicitante | I1: Actividades receptor | J1: Estado | K1: Comentario solicitante | L1: Comentario receptor | M1: Comentario supervisor | N1: Creado | O1: Respondido receptor | P1: Decidido | Q1: Supervisor | R1: Aplicación | S1: Visto solicitante | T1: Visto receptor | U1: Revisado coordinación | V1: Revisor | W1: Comentario revisor | X1: Hilo correo
A2: imvfw4d116dhj | B2: 2026-10 | C2: 21 | D2: 3217561 | E2: Claudia Flores | F2: 2823133 | G2: Cesar Campos | H2: ["HB6\nCurso B767\n(08:30-17:30hrs)"] | I2: ["RESERVA IET"] | J2: Aprobado | L2: Acepto el cambio. Muchas gracias. | N2: 46314.69 | O2: 46314.693 | P2: 46315.558 | Q2: Virginia Sullca | R2: Aplicado en el Google Sheet y sincronizado · 2026-10-20 | S2: pendiente | T2: en_supervisor | U2: 46314.696 | V2: Virginia Sullca | X2: {"thread":"1a15683530d90c78","ultimo":"<CAOYCRE-No45S-o8SsuOSUtR3h9paq-EHRcqxgZ+NrdMORQLjcA@mail.gmail.com>","refs":"<CAOYCRE95wJ27hNa8yb5AcuX+zxRrztpf+nHr0b7aig02pMA6Nw@mail.gmail.com> <CAOYCRE9+TjnBVr5oZvgJZJDT4gjErR5VsYyKyOCp1s_o8KeN=g@mail.gmail.com> <CAOYCRE84LtL6AYzpBYE_3DwGx=f3hBeJe-NvR7XPFjzOpRH1Sg@mail.gmail.com> <CAOYCRE-No45S-o8SsuOSUtR3h9paq-EHRcqxgZ+NrdMORQLjcA@mail.gmail.com>","dest":["claudia.floresf@latam.com","cesar.campos@latam.com","antonella.cotrina@latam.com","virginia.sullca@latam.com","jorge.bodero@latam.com"]}

Sheet TiposActividad
A1: Orden | B1: Tipo | C1: Palabras clave | D1: Color fondo | E1: Color texto | F1: Activo | G1: Notas
A2: 1 | B2: Do | C2: DO | D2: #ffffff | E2: #000000 | F2: NO
A3: 2 | B3: Vacaciones | C3: VACACIONES | D3: #ffffcc | E3: #000000 | F3: NO
A4: 3 | B4: Lck b767 | C4: LCK B767; BLANCO; HABILITACIÓN * | D4: #ffc000 | E4: #000000 | F4: SI
A5: 4 | B5: Adm | C5: ADM; RESERVA IET; RESERVA IET TARDE | D5: #d9d9d9 | E5: #000000 | F5: NO
A6: 5 | B6: Lck a320f | C6: LCK A320F; REENTRENAMIENTO A320F; REENTRENAMIENTO A320F* | D6: #f7caac | E6: #000000 | F6: NO
A7: 6 | B7: Inicial g10 | C7: INICIAL G10 | D7: #a64d79 | E7: #ffffff | F7: NO
A8: 7 | B8: Taller voluntario de seguridad | C8: TALLER VOLUNTARIO DE SEGURIDAD; REUNIÓN INSTRUCTORES; DESAYUNO | D8: #ffff00 | E8: #000000 | F8: NO
A9: 8 | B9: Ho file tarde | C9: HO FILE TARDE; VUELO IDA LIM SCL; COBUS SCL A321XLR | D9: #999999 | E9: #000000 | F9: NO
A10: 9 | B10: Inicial g11 | C10: INICIAL G11 | D10: #00ff00 | E10: #000000 | F10: NO
A11: 10 | B11: Curso 50% | C11: CURSO 50%; IOSA | D11: #ff9900 | E11: #000000 | F11: NO
A12: 11 | B12: Rti: práctica | C12: RTI: PRÁCTICA; RTI: VIRTUAL | D12: #cce0f4 | E12: #000000 | F12: NO
A13: 12 | B13: Fds | C13: FDS | D13: #0000ff | E13: #ffffff | F13: NO
... A29: 28 | B29: Chequeo dgac b767 | C29: CHEQUEO DGAC B767 | D29: #e69138 | E29: #000000 | F29: NO

Sheet VacacionesProgramado
A1: BP | B1: Mes | C1: Días
A2: 29530 | B2: 2026-05 | C2: 8
A3: 29530 | B3: 2026-06 | C3: 7
A4: 29530 | B4: 2026-10 | C4: 15
A5: 29530 | B5: 2026-12 | C5: 11
A6: 71348 | B6: 2026-02 | C6: 7
A7: 967092 | B7: 2026-01 | C7: 15
A8: 967092 | B8: 2026-02 | C8: 7
A9: 967092 | B9: 2026-08 | C9: 24
A10: 1271571 | B10: 2026-02 | C10: 6
A11: 1271571 | B11: 2026-03 | C11: 1
A12: 1271571 | B12: 2026-05 | C12: 7
A13: 1271571 | B13: 2026-08 | C13: 7
... A69: 3852423 | B69: 2026-08 | C69: 16

Sheet VacacionesPeriodos
A1: BP | B1: Periodo | C1: Derecho | D1: Tomados (referencia)
A2: 29530 | B2: 2025-26 | C2: 40 | D2: 41
A3: 29530 | B3: 2026-27 | C3: 41
A4: 71348 | B4: 2025-26 | C4: 45 | D4: 7
A5: 71348 | B5: 2026-27 | C5: 45
A6: 967092 | B6: 2025-26 | C6: 45 | D6: 46
A7: 967092 | B7: 2026-27 | C7: 45
A8: 1271571 | B8: 2025-26 | C8: 45 | D8: 21
A9: 1271571 | B9: 2026-27 | C9: 45
A10: 2369624 | B10: 2025-26 | C10: 44 | D10: 42
A11: 2369624 | B11: 2026-27 | C11: 45
A12: 2369641 | B12: 2025-26 | C12: 44 | D12: 42
A13: 2369641 | B13: 2026-27 | C13: 45
A14: 2396710 | B14: 2025-26 | C14: 43 | D14: 31
A15: 2396710 | B15: 2026-27 | C15: 45
A16: 2415373 | B16: 2025-26 | C16: 44 | D16: 44
A17: 2415373 | B17: 2026-27 | C17: 45
A18: 2440915 | B18: 2025-26 | C18: 44 | D18: 44
A19: 2440915 | B19: 2026-27 | C19: 45
A20: 2604360 | B20: 2025-26 | C20: 41 | D20: 40
A21: 2604360 | B21: 2026-27 | C21: 42
A22: 2713993 | B22: 2025-26 | C22: 45 | D22: 41
A23: 2713993 | B23: 2026-27 | C23: 45
A24: 2823133 | B24: 2025-26 | C24: 40 | D24: 41
A25: 2823133 | B25: 2026-27 | C25: 41
A26: 2843319 | B26: 2025-26 | C26: 42 | D26: 42
A27: 2843319 | B27: 2026-27 | C27: 43
A28: 3134911 | B28: 2025-26 | C28: 41 | D28: 46
A29: 3134911 | B29: 2026-27 | C29: 42
A30: 3189967 | B30: 2025-26 | C30: 40 | D30: 41
A31: 3189967 | B31: 2026-27 | C31: 41
A32: 3217561 | B32: 2025-26 | C32: 40 | D32: 41
A33: 3217561 | B33: 2026-27 | C33: 41
A34: 3750335 | B34: 2025-26 | C34: 36 | D34: 35
A35: 3750335 | B35: 2026-27 | C35: 37
A36: 3779550 | B36: 2025-26 | C36: 38 | D36: 38
A37: 3779550 | B37: 2026-27 | C37: 39
A38: 3796947 | B38: 2025-26 | C38: 38 | D38: 8
A39: 3796947 | B39: 2026-27 | C39: 39
A40: 3841387 | B40: 2025-26 | C40: 37 | D40: 39
...

Sheet Vacaciones
A1: BP | B1: Nombre | C1: Fecha DGAC original | D1: Fecha DGAC 2025 | E1: Fecha DGAC 2026 | F1: Derecho 2025-26 | G1: Derecho 2026-27 | H1: Tomados 2025-26 | I1: Programado por mes 2026
A2: 29530 | B2: GUERRA SUAREZ JAZMIN | C2: 40567 | D2: 45681 | E2: 46046 | F2: 40 | G2: 41 | H2: 41 | I2: 5:8; 6:7; 10:15; 12:11
A3: 71348 | B3: MOZ MONTES KARLA LISSETTE | C3: 38223 | D3: 45893 | E3: 46258 | F3: 45 | G3: 45 | H3: 7 | I3: 2:7
A4: 967092 | B4: DAVILA BELLO MARIA ERIKA | C4: 38139 | D4: 45809 | E4: 46174 | F4: 45 | G4: 45 | H4: 46 | I4: 1:15; 2:7; 8:24
A5: 1271571 | B5: RONDON BARRUTIA CHRISTIAN ERIC | D5: 45950 | E5: 46315 | F5: 45 | G5: 45 | H5: 21 | I5: 2:6; 3:1; 5:7; 8:7
A6: 2369624 | B6: NAJAR CRUZ PATRICIA DEL PILAR | C6: 39187 | D6: 45762 | E6: 46127 | F6: 44 | G6: 45 | H6: 42 | I6: 1:6; 4:7; 8:7; 9:7; 10:15
A7: 2369641 | B7: TORRES POLO ELIZABETH DEL PILAR | C7: 39197 | D7: 45772 | E7: 46137 | F7: 44 | G7: 45 | H7: 42 | I7: 1:12; 6:8; 9:15; 11:7
A8: 2396710 | B8: CORREA GARCIA JUAN SEBASTIAN | D8: 45823 | E8: 46188 | F8: 43 | G8: 45 | H8: 31 | I8: 4:18; 6:8; 11:5
A9: 2415373 | B9: SALAS COSIO MILAGROS PATRICIA | C9: 39295 | D9: 45870 | E9: 46235 | F9: 44 | G9: 45 | H9: 44 | I9: 5:29; 10:15
A10: 2440915 | B10: FERNANDEZ GARCIA JUDITH JULIET | C10: 39356 | D10: 45931 | E10: 46296 | F10: 44 | G10: 45 | H10: 44 | I10: 1:7; 2:14; 8:15; 10:8
A11: 2604360 | B11: CARRASCO BENAVIDES ROSA MARIELLA | C11: 40301 | D11: 45780 | E11: 46145 | F11: 41 | G11: 42 | H11: 40 | I11: 2:10; 5:8; 9:15; 11:7
A12: 2713993 | B12: RUIZ RIOJA FIORELLA DEL PILAR | D12: 45689 | E12: 46054 | F12: 45 | G12: 45 | H12: 41 | I12: 3:5; 5:2; 7:1; 10:29; 11:4
A13: 2823133 | B13: CAMPOS CONCHE CESAR AUGUSTO | C13: 40546 | D13: 45660 | E13: 46025 | F13: 40 | G13: 41 | H13: 41 | I13: 6:15; 7:15; 12:11
A14: 2843319 | B14: SANTA CRUZ HUAMAN KAREN | C14: 40026 | D14: 45870 | E14: 46235 | F14: 42 | G14: 43 | H14: 42 | I14: 1:14; 7:12; 10:16
A15: 3134911 | B15: ZAPATA GARAYAR JAVIER RICARDO SALVADOR | C15: 40462 | D15: 45941 | E15: 46306 | F15: 41 | G15: 42 | H15: 46 | I15: 3:23; 10:23
A16: 3189967 | B16: SEGOVIA TAPIA RAY KEVIN | C16: 40546 | D16: 45660 | E16: 46025 | F16: 40 | G16: 41 | H16: 41 | I16: 6:7; 8:16; 9:18
A17: 3217561 | B17: FLORES FUENTES DAVILA CLAUDIA ALEXANDRA | C17: 40567 | D17: 45681 | E17: 46046 | F17: 40 | G17: 41 | H17: 41 | I17: 4:15; 9:15; 11:11
A18: 3750335 | B18: MENDEZ RUCOBA JEFFERSON JOHONATAN | C18: 42186 | D18: 45839 | E18: 46204 | F18: 36 | G18: 37 | H18: 35 | I18: 4:20; 9:8; 11:7
A19: 3779550 | B19: ACURIO DARGENT JENNIFERT MILAGROS | C19: 41470 | D19: 45853 | E19: 46218 | F19: 38 | G19: 39 | H19: 38 | I19: 4:8; 6:15; 11:15
A20: 3796947 | B20: RAFAEL ANTONIO NIETO | C20: 41526 | F20: 38 | G20: 39 | H20: 8 | I20: 9:8
A21: 3841387 | B21: CELIZ ROSSI GIANFRANCO PAOLO | C21: 41656 | D21: 45674 | E21: 46039 | F21: 37 | G21: 38 | H21: 39 | I21: 1:8; 6:7; 7:17; 8:7
A22: 3852423 | B22: UNGARO GUTIERREZ SARA GABRIELA | C22: 41835 | D22: 45853 | E22: 46218 | F22: 37 | G22: 38 | H22: 39 | I22: 3:8; 5:8; 6:7; 8:16

Sheet VacacionesDias
A1: BP | B1: Fecha
A2: 29530 | B2: 45299
A3: 29530 | B3: 45300
A4: 29530 | B4: 45301
A5: 29530 | B5: 45302
A6: 29530 | B6: 45303
A7: 29530 | B7: 45304
A8: 29530 | B8: 45305
A9: 29530 | B9: 45306
A10: 29530 | B10: 45307
A11: 29530 | B11: 45308
A12: 29530 | B12: 45309
A13: 29530 | B13: 45310
... A2307: 3852423 | B2307: 46257

Sheet VacacionesBloques
A1: BP | B1: Desde | C1: Hasta | D1: Días | E1: Registrado
A2: 29530 | B2: 46296 | C2: 46310 | D2: 15 | E2: 46230
A3: 29530 | B3: 46377 | C3: 46387 | D3: 11 | E3: 46230
A4: 1271571 | B4: 46279 | C4: 46313 | D4: 24 | E4: 46227
A5: 2369624 | B5: 46296 | C5: 46310 | D5: 15 | E5: 46230
A6: 2369624 | B6: 46266 | C6: 46272 | D6: 7 | E6: 46230
A7: 2369641 | B7: 46282 | C7: 46295 | D7: 14 | E7: 46230
A8: 2369641 | B8: 46349 | C8: 46356 | D8: 8 | E8: 46230
A9: 2415373 | B9: 46300 | C9: 46307 | D9: 8 | E9: 46234
A10: 2415373 | B10: 46308 | C10: 46314 | D10: 7 | E10: 46235
A11: 2440915 | B11: 46303 | C11: 46310 | D11: 8 | E11: 46230
A12: 2604360 | B12: 46281 | C12: 46295 | D12: 15 | E12: 46233
A13: 2604360 | B13: 46381 | C13: 46387 | D13: 7 | E13: 46233
... A23: 3779550 | B23: 46328 | C23: 46342 | D23: 15 | E23: 46237

Sheet SolicitudesVacaciones
A1: ID | B1: BP | C1: Nombre | D1: Días | E1: Cantidad | F1: Enviada | G1: Estado | H1: Decidida | I1: Decidida por | J1: Comentario instructor | K1: Comentario coordinación | L1: Respuesta instructor | M1: Motivo revisión | N1: Respondida | O1: Revisión atendida

Sheet Roles
A1: mes | B1: json | C1: actualizadoAt | D1: origen
A2: 2026-01 | B2: {"mes":"2026-01","fuente":"01 - Rol Instructores LP ENERO","hoja":"ENERO","instructores":[{"bp":"2713993","nombre":"Fiorella Ruiz","dias":["DO","HO FILE","FDS","FDS","LCK B767\n- LIM-MIA\n- LA 2694 (13:30-19:30 hrs)","Habilitación B767*\n- MIA-LIM\n- LA 2699 (23:10-05:00 hrs)","Blanco","Reentrenamiento A320F","RTI: PRÁCTICA\nA320F / B767\n(08:30-17:30 hrs)\nINS APOYO TM","FDS","FDS","LCK B787\n- LIM-SCL\n- LA 2697 (09:35-13:00 hrs)\nRecalificación B787\n- SCL-LIM\n- LA 2696 (16:00-19:45 hrs)","HO FILE","LCK B787\n- LIM-SCL\n- LA 2697 (09:35-13:00 hrs)\nHabilitación B787*\n- SCL-LIM\n- LA 2696 (16:00-19:45 hrs)","HO FILE TARDE","RTI: PRÁCTICA\nA320F / B767 / B787\n(08:30-17:30 hrs)\nINS TITULAR","FDS","FDS","LCK B767\n- LIM-MIA\n- LA 2694 (13:30-19:30 hrs)","Reentrenamiento B767\n- MIA-LIM\n- LA 2699 (23:10-05:00 hrs)","Blanco","Inicial G13\nCHEQUEO DGAC\nLA2258 - LA2259 \nLIM - CJA - LIM","HANDS ON B767","FDS","FDS","HO FILE","HO FILE","Inicial G13\nTALLER DÍA 1","HANDS ON B787","Chequeo DGAC B787\n- LIM-SCL\n- LA 2697 (09:35-13:00 hrs)\nHabilitación B787\n- SCL-LIM\n- LA 2696 (16:00-19:45 hrs)","FDS"],"bg":["#ffffff","#999999","#0000ff","#0000ff","#ffc000","#ffc000","#ffc000","#f7caac","#cce0f4","#0000ff","#0000ff","#e88888","#999999","#e88888","#999999","#cce0f4","#0000ff","#0000ff","#ffc000","#ffc000","#ffc000","#38761d","#ffff00","#0000ff","#0000ff","#999999","#999999","#38761d","#ffff00","#e88888","#0000ff"],"fg":["#000000","#000000","#ffffff","#ffffff","#000000","#000000","#000000","#000000","#000000","#ffffff","#ffffff","#000000","#000000","#000000","#000000","#000000","#ffffff","#ffffff","#000000","#000000","#000000","#ffffff","#000000","#ffffff","#ffffff","#000000","#000000","#ffffff","#000000","#000000","#ffffff"]},{"bp":"2396710","nombre":"Sebastian Correa","dias":["DO","Inicial G13 (Recuperatorio)","FDS","FDS","REVA ANUAL INSTRUCTORES\n ALUMNO","Habilitación B787\n- LIM-SCL\n- LA 2697 (09:35-13:00 hrs)\nReentrenamiento B787\n- SCL-LIM\n- LA 2696 (16:00-19:45 hrs)","HO FILE TARDE","HO FILE","HO FILE","FDS","FDS","Ditching Presencial B787 + HANDS ON\nTripulación de Mando\nLP\n(08:30-17:30 hrs)","Inicial G1","RTI: PRÁCTICA\nA320F / B767 / B787\n(08:30-17:30 hrs)\nINS APOYO","RTI: PRÁCTICA\nA320F / B767 / B787\n(08:30-17:30 hrs)\nINS APOYO TM","Inicial G1","FDS","FDS","LCK B787\n- LIM-SCL\n- LA 2697 (09:35-13:00 hrs)\nLCK B787\n- SCL-LIM\n- LA 2696 (16:00-19:45 hrs)","HO FILE TARDE","LCK B787\n- LIM-SCL\n- LA 2697 (09:35-13:00 hrs)\nHabilitación B787*\n- SCL-LIM\n- LA 2696 (16:00-19:45 hrs)","HO FILE TARDE","LCK A320F\nLIM-AQP-LIM\nLA 2123 (09:20-11:00 hrs)\nLA 2124 (11:35-13:10 hrs)\nLCK A320F\nLIM-CIX-LIM\nLA 2312 (14:25-15:55 hrs)\nLA 2313 (16:35-18:00 hrs)","FDS","FDS","Chequeo DGAC B787\n- LIM-SCL\n- LA 2697 (09:35-13:00 hrs)\nChequeo DGAC B787\n- SCL-LIM\n- LA 2696 (16:00-19:45 hrs)","HO FILE TARDE","Chequeo LATAM B787\n- LIM-SCL\n- LA 2697 (09:35-13:00 hrs)\nLCK B787\n- SCL-LIM\n- LA 2696 (16:00-19:45 hrs)","Inicial G2 (TARDE)","CURSO REFRESCO IDE","FDS"],"bg":["#ffffff","#38761d","#0000ff","#0000ff","#ff9900","#e88888","#999999","#999999","#999999","#0000ff","#0000ff","#ff4b4f","#fff2cc","#cce0f4","#cce0f4","#fff2cc","#0000ff","#0000ff","#e88888","#999999","#e88888","#999999","#f7caac","#0000ff","#0000ff","#e88888","#999999","#e88888","#b4a7d6","#00ffff","#0000ff"],"fg":["#000000","#ffffff","#ffffff","#ffffff","#000000","#000000","#000000","#000000","#000000","#ffffff","#ffffff","#ffffff","#000000","#000000","#000000","#000000","#ffffff","#ffffff","#000000","#000000","#000000","#000000","#000000","#ffffff","#ffffff","#000000","#000000","#000000","#ffffff","#000000","#ffffff"]},{"bp":"1271571","nombre":"Christian Rondon","dias":["DO","CAPACITACION RRVV","FDS","FDS","HO FILE","Inicial G13","LCK B787\n- LIM-SCL\n- LA 2697 (09:35-13:00 hrs)\nHABILITACIÓN B787\n- SCL-LIM\n- LA 2696 (16:00-19:45 hrs)","LEVANTAMIENTO INFORMACIÓN INSTRUCCION (TARDE)","REUNIÓN DE SEGURIDAD","FDS","FDS","REVA ANUAL INSTRUCTORES\n ALUMNO","Chequeo LATAM B787\n- LIM-SCL\n- LA 2697 (09:35-13:00 hrs)\nChequeo LATAM B787\n- SCL-LIM\n- LA 2696 (16:00-19:45 hrs)","HO FILE TARDE","ACT\nRRVV","RTI: PRÁCTICA\nA320F / B767 / B787\n(08:30-17:30 hrs)\nINS APOYO","FDS","FDS","Blanco Recojo","LCK B767\n- LIM-MIA\n- LA 2480 (00:15-06:15 hrs)","Chequeo LATAM B767\n- MIA-LIM\n- LA 2481 (15:55-21:40 hrs)","HO FILE TARDE","HANDS ON B787","FDS","FDS","LCK B767\n- LIM-MIA\n- LA 2694 (13:30-19:30 hrs)","Habilitación B767*\n- MIA-LIM\n- LA 2699 (23:10-05:00 hrs)","Blanco","LCK B787\n- LIM-SCL\n- LA 2697 (09:35-13:00 hrs)\nHabilitación B787*\n- SCL-LIM\n- LA 2696 (16:00-19:45 hrs)","CURSO REFRESCO IDE","FDS"],"bg":["#ffffff","#d0e0e3","#0000ff","#0000ff","#999999","#38761d","#e88888","#999999","#999999","#0000ff","#0000ff","#ff9900","#e88888","#999999","#ffff00","#cce0f4","#0000ff","#0000ff","#ffc000","#ffc000","#ffc000","#999999","#ffff00","#0000ff","#0000ff","#ffc000","#ffc000","#ffc000","#e88888","#00ffff","#0000ff"],"fg":["#000000","#000000","#ffffff","#ffffff","#000000","#ffffff","#000000","#000000","#000000","#ffffff","#ffffff","#000000","#000000","#000000","#000000","#000000","#ffffff","#ffffff","#000000","#000000","#000000","#000000","#000000","#ffffff","#ffffff","#000000","#000000","#000000","#000000","#000000","#ffffff"]},{"bp":"2843319","nombre":"Karen Santa Cruz","dias":["DO","CAPACITACION RRVV","DO","DO","Blanco Recojo","LCK B767\n- LIM-MIA\n- LA 2480 (00:15-06:15 hrs)","Acompañamiento de Servicio B767\n- MIA-LIM\n- LA 2481 (15:55-21:40 hrs)","Inicial G13 (Recuperatorio)","RTI: PRÁCTICA\nA320F / B767\n(08:30-17:30 hrs)\nINS APOYO","DO","DO","REVA ANUAL INSTRUCTORES INSTRUCTOR","AUDITORIA PROCAB","CURSO 50%","DO","VACACIONES","VACACIONES","VACACIONES","VACACIONES","VACACIONES","VACACIONES","VACACIONES","VACACIONES","VACACIONES","VACACIONES","VACACIONES","VACACIONES","VACACIONES","VACACIONES","CURSO REFRESCO IDE","HO FILE"],"bg":["#ffffff","#d0e0e3","#ffffff","#ffffff","#ffc000","#ffc000","#ffc000","#38761d","#cce0f4","#ffffff","#ffffff","#ff9900","#ffff00","#ffe599","#ffffff","#ffffcc","#ffffcc","#ffffcc","#ffffcc","#ffffcc","#ffffcc","#ffffcc","#ffffcc","#ffffcc","#ffffcc","#ffffcc","#ffffcc","#ffffcc","#ffffcc","#00ffff","#999999"],"fg":["#000000","#000000","#000000","#000000","#000000","#000000","#000000","#ffffff","#000000","#000000","#000000","#000000","#000000","#000000","#000000","#000000","#000000","#000000","#000000","#000000","#000000","#000000","#000000","#000000","#000000","#000000","#000000","#000000","#000000","#000000","#000000"]},{"bp":"3779550","nombre":"Jennifert Acurio","dias":["DO","DO","DO","DO","HO FILE","LCK A320F\nLIM-AQP-LIM\nLA 2123 (09:20-11:00 hrs)\nLA 2124 (11:35-13:10 hrs)","Inicial G1","Inicial G2","RTI: PRÁCTICA\nA320F / B767\n(08:30-17:30 hrs)\nINS TITULAR","DO","DO","Habilitación B787 (CST)\n- LIM-SCL\n- LA 2697 (09:35-13:00 hrs)\nHabilitación B787 (CST)\n- SCL-LIM\n- LA 2696 (16:00-19:45 hrs)","B","Reva de Servicio\n(08:30-17:30 hrs)\nDÍA 2","LCK B767\n- LIM-BOG\n- LA 2489 (13:00-16:15 hrs)\nLCK B767\n- BOG-LIM\n- LA 2488 (17:20-20:45 hrs)","HO FILE TARDE","DO","DO","HO FILE","Blanco Recojo","LCK B767\n- LIM-MIA\n- LA 2480 (00:15-06:15 hrs)","Acompañamiento de Servicio B767\n- MIA-LIM\n- LA 2695 (16:20-22:00 hrs)","HO FILE TARDE","DO","DO","HO FILE","LCK A320F (VIGILANCIA DGAC) + HAB A320F.\nLA2306 - LA2307\nLIM - PIU - LIM","HO FILE","RTI: PRÁCTICA\nA320F / B767\n(08:30-17:30 hrs)\nINS APOYO TM","CURSO REFRESCO IDE","DO"],"bg":["#ffffff","#ffffff","#ffffff","#ffffff","#999999","#f7caac","#fff2cc","#b4a7d6","#cce0f4","#ffffff","#ffffff","#e88888","#ffffff","#2f5496","#ffc000","#999999","#ffffff","#ffffff","#999999","#ffc000","#ffc000","#ffc000","#999999","#ffffff","#ffffff","#999999","#f7caac","#999999","#cce0f4","#00ffff","#ffffff"],"fg":["#000000","#000000","#000000","#000000","#000000","#000000","#000000","#ffffff","#000000","#000000","#000000","#000000","#000000","#ffffff","#000000","#000000","#000000","#000000","#000000","#000000","#000000","#000000","#000000","#000000","#000000","#000000","#000000","#000000","#000000","#000000","#000000"]},{"bp":"29530","nombre":"Jazmin Guerra","dias":["DO","HO FILE","DO","DO","Inicial G13","Inicial G1","Habilitación B787 (CST)\n- LIM-SCL\n- LA 2697 (09:35-13:00 hrs)\nHabilitación B787 (CST)\n- SCL-LIM\n- LA 2696 (16:00-19:45 hrs)","DO","DO","DO","DO","LCK B767\n- LIM-MIA\n- LA 2694 (13:30-19:30 hrs)","Habilitación 767*\n- MIA-LIM\n- LA 2699 (23:10-05:00 hrs)","Blanco","RTI: PRÁCTICA\nA320F / B767 / B787\n(08:30-17:30 hrs)\nINS APOYO TM","HO FILE","DO","DO","ACOMPAÑAMIENTO EN VUELO","LCK A320F + HAB. A320F\nLIM-CUZ-LIM\nLA2075/LA2076","Blanco Recojo","LCK B767\n- LIM-MIA\n- LA 2480 (00:15-06:15 hrs)","Habilitación B767\n- MIA-LIM\n- LA 2481 (15:55-21:40 hrs)","DO","DO","Situaciones de Emergencia B767\nTripulación de Mando\nLP\n(08:30-17:30 hrs)","Reva de Servicio\n(08:30-17:30 hrs)\nDÍA 1","Ditching Presencial B767 + HANDS ON\nTripulación de Mando\nLP\n(08:30-17:30 hrs)","HO FILE","CURSO REFRESCO IDE","DO"],"bg":["#ffffff","#999999","#ffffff","#ffffff","#38761d","#fff2cc","#e88888","#ffffff","#ffffff","#ffffff","#ffffff","#ffc000","#ffc000","#ffc000","#cce0f4","#999999","#ffffff","#ffffff","#a2c4c9","#f7caac","#ffc000","#ffc000","#ffc000","#ffffff","#ffffff","#ff4b4f","#2f5496","#ff4b4f","#999999","#00ffff","#ffffff"],"fg":["#000000","#000000","#000000","#000000","#ffffff","#000000","#000000","#000000","#000000","#000000","#000000","#000000","#000000","#000000","#000000","#000000","#000000","#000000","#ffffff","#000000","#000000","#000000","#000000","#000000","#000000","#ffffff","#ffffff","#ffffff","#000000","#000000","#000000"]},{"bp":"3217561","nombre":"Claudia Flores","dias":["DO","DO","DO","DO","LCK A320F\nLIM-AQP-LIM\nLA 2115 (13:55-15:25 hrs)\nLA 2114 (16:00-17:35 hrs)","REVA ANUAL INSTRUCTORES\n ALUMNO","LCK A320F\r\nLIM-TCQ-LIM\r\nLA 2245 (09:00-10:50 hrs)\r\nLA 2244 (11:25-13:15 hrs)\r\nLCK A320F\r\nLIM-TPP-LIM\r\nLA 2087 (14:10-15:35 hrs)\r\nLA 2088 (16:10-17:30 hrs)","Inicial G1","Inicial G1","DO","DO","TALLER VOLUNTARIO SEG","HANDS ON B767","HO FILE","Reva de Servicio\n(08:30-17:30 hrs)\nDÍA 1","HO FILE","DO","DO","LCK A320F\r\nLIM-AQP-LIM\r\nLA 2123 (09:20-11:00 hrs)\r\nLA 2124 (11:35-13:10 hrs)\r\nLCK A320F\r\nLIM-CUZ-LIM\r\nLA 2075 (14:25-15:50 hrs)\r\nLA 2076 (16:25-18:00 hrs)","LCK ALUMNO A320F (CCM)\nLIM-PCL-LIM\nLA 2360 (14:05-15:20 hrs)\nLA 2361 (15:55-17:10 hrs)\nLIM-TRU-LIM\nLA 2139 (18:00-19:10 hrs)\nLA 2140 (19:45-21:00 hrs)","HO FILE TARDE","Inicial G13\nCHEQUEO DGAC \nLA2306 - LA2307 \nLIM - PIU - LIM","Habilitación B767\n- LIM-BOG\n- LA 2489 (13:00-16:15 hrs)\nChequeo DGAC B767\n- BOG-LIM\n- LA 2488 (17:20-20:45 hrs)","DO","DO","LCK A320F\nLIM-AQP-LIM\nLA 2115 (13:55-15:25 hrs)\nLA 2114 (16:00-17:35 hrs)","HO FILE","LCK A320F\r\nLIM-AQP-LIM\r\nLA 2123 (09:20-11:00 hrs)\r\nLA 2124 (11:35-13:10 hrs)\r\nLCK A320F\r\nLIM-PCL-LIM\r\nLA 2360 (14:05-15:20 hrs)\r\nLA 2361 (15:55-17:10 hrs)","Inicial G1","CURSO REFRESCO IDE","DO"],"bg":["#ffffff","#ffffff","#ffffff","#ffffff","#f7caac","#ff9900","#f7caac","#fff2cc","#fff2cc","#ffffff","#ffffff","#ffff00","#ffff00","#999999","#2f5496","#999999","#ffffff","#ffffff","#f7caac","#f7caac","#999999","#38761d","#ffc000","#ffffff","#ffffff","#f7caac","#999999","#f7caac","#fff2cc","#00ffff","#ffffff"],"fg":["#000000","#000000","#000000","#000000","#000000","#000000","#000000","#000000","#000000","#000000","#000000","#000000","#000000","#000000","#ffffff","#000000","#000000","#000000","#000000","#000000","#000000","#ffffff","#000000","#000000","#000000","#000000","#000000","#000000","#000000","#000000","#000000"]},{"bp":"2963161","nombre":"Luis Bacigalupo","dias":["DO","CAPACITACION RRVV","DO","DO","REVA ANUAL INSTRUCTORES\n ALUMNO","VISITA AL CAE CON COMUNICACIONES INTERNAS Y EXTERNAS","VISITA AL CAE CON COMUNICACIONES INTERNAS Y EXTERNAS","DO","DO","DO","DO","Blanco Recojo","LCK B767\n- LIM-MIA\n- LA 2480 (00:15-06:15 hrs)","Pasajero 767\n- MIA-LIM\n- LA 2699 (23:10-05:30 hrs)","Blanco","CURSO 50%","DO","DO","Inicial G1","Reva de Servicio\n(08:30-17:30 hrs)\nDÍA 1","INICIAL G13 \nCHEQUEO DGAC\nLA2023 - LA2024\n LIM - PEM - LIM","LCK B767\n- LIM-BOG\n- LA 2489 (13:00-16:15 hrs)\nLCK B767\n- BOG-LIM\n- LA 2488 (17:20-20:45 hrs)","HO FILE TARDE","DO","DO","Inicial G13\nCHEQUEO LATAM\nLA2023 - LA2024 - LA2061 - LA2062\nLIM - PEM - LIM - CUZ - LIM","Blanco Recojo","LCK B767\n- LIM-MIA\n- LA 2480 (00:15-06:15 hrs)","Habilitación B767\n- MIA-LIM\n- LA 2695 (16:20-22:00 hrs)","HO FILE TARDE","DO"],"bg":["#ffffff","#d0e0e3","#ffffff","#ffffff","#ff9900","#999999","#999999","#ffffff","#ffffff","#ffffff","#ffffff","#ffc000","#ffc000","#ffc000","#ffc000","#ffe599","#ffffff","#ffffff","#fff2cc","#2f5496","#38761d","#ffc000","#999999","#ffffff","#ffffff","#38761d","#ffc000","#ffc000","#ffc000","#999999","#ffffff"],"fg":["#000000","#000000","#000000","#000000","#000000","#000000","#000000","#000000","#000000","#000000","#000000","#000000","#000000","#000000","#000000","#000000","#000000","#000000","#000000","#ffffff","#ffffff","#000000","#000000","#000000","#000000","#ffffff","#000000","#000000","#000000","#000000","#000000"]},{"bp":"71348","nombre":"Karla Moz","dias":["LP","LP","LP","LP","LP","LP","LP","LP","LP","LP","LP","LP","LP","LP","LP","LP","LP","LP","LP","LP","LP","LP","LP","LP","LP","LP","LP","LP","LP","LP","LP"],"bg":["#ffffff","#ffffff","#ffffff","#ffffff","#ffffff","#ffffff","#ffffff","#ffffff","#ffffff","#ffffff","#ffffff","#ffffff","#ffffff","#ffffff","#ffffff","#ffffff","#ffffff","#ffffff","#ffffff","#ffffff","#ffffff","#ffffff","#ffffff","#ffffff","#ffffff","#ffffff","#ffffff","#ffffff","#ffffff","#ffffff","#ffffff"],"fg":["#000000","#000000","#000000","#000000","#000000","#000000","#000000","#000000","#000000","#000000","#000000","#000000","#000000","#000000","#000000","#000000","#000000","#000000","#000000","#000000","#000000","#000000","#000000","#000000","#000000","#000000","#000000","#000000","#000000","#000000","#000000"]},{"bp":"967092","nombre":"Erika Dávila","dias":["VACACIONES","VACACIONES","VACACIONES","VACACIONES","VACACIONES","VACACIONES","VACACIONES","Reva de Servicio\n(08:30-17:30 hrs)\nDÍA 1","Reva de Servicio\n(08:30-17:30 hrs)\nDÍA 2","DO","DO","REVA ANUAL INSTRUCTORES\n ALUMNO","RTI: VIRTUAL\nA320F / B767 / B787\n(08:30-17:30 hrs)\nINS TITULAR","RTI: PRÁCTICA\nA320F / B767 / B787\n(08:30-17:30 hrs)\nINS TITULAR","RTI: PRÁCTICA\nA320F / B767 / B787\n(08:30-17:30 hrs)\nINS APOYO TM","HO FILE","DO","DO","CURSO 50%","CURSO 50%","Reva de Servicio\n(08:30-17:30 hrs)\nDÍA 2","Inicial G2","DO","VACACIONES","VACACIONES","VACACIONES","VACACIONES","VACACIONES","VACACIONES","VACACIONES","VACACIONES"],"bg":["#ffffcc","#ffffcc","#ffffcc","#ffffcc","#ffffcc","#ffffcc","#ffffcc","#2f5496","#2f5496","#ffffff","#ffffff","#ff9900","#cce0f4","#cce0f4","#cce0f4","#999999","#ffffff","#ffffff","#ffe599","#ffe599","#2f5496","#b4a7d6","#ffffff","#ffffcc","#ffffcc","#ffffcc","#ffffcc","#ffffcc","#ffffcc","#ffffcc","#ffffcc"],"fg":["#000000","#000000","#000000","#000000","#000000","#000000","#000000","#ffffff","#ffffff","#000000","#000000","#000000","#000000","#000000","#000000","#000000","#000000","#000000","#000000","#000000","#ffffff","#ffffff","#000000","#000000","#000000","#000000","#000000","#000000","#000000","#000000","#000000"]},{"bp":"2369641","nombre":"Elizabeth Torres","dias":["VACACIONES","VACACIONES","VACACIONES","VACACIONES","VACACIONES","VACACIONES","VACACIONES","VACACIONES","VACACIONES","VACACIONES","VACACIONES","VACACIONES","ENTREVISTAS","HO FILE","ACT\nRRVV","LCK A320F\nLIM-PCL-LIM\nLA2360/LA2361","DO","DO","HO FILE","Inicial G13\nCHEQUEO LATAM\nLA2125 - LA2126 - LA2308 - LA2309\t\nLIM - PIU - LIM - PIU - LIM","REVA ANUAL INSTRUCTORES\n ALUMNO","HABILITACIÓN A320F (CCM)\nLIM-TBP-LIM\nLA 2052 (14:00-16:00 hrs)\nLA 2051 (16:40-18:20 hrs)","LCK B767\n- LIM-BOG\n- LA 2489 (13:00-16:15 hrs)\nLCK B767\n- BOG-LIM\n- LA 2488 (17:20-20:45 hrs)","DO","DO","Blanco Recojo","LCK B767\n- LIM-MIA\n- LA 2480 (00:15-06:15 hrs)","Habilitación B767*\n- MIA-LIM\n- LA 2481 (15:55-21:40 hrs)","HO FILE TARDE","Reva de Servicio\n(08:30-17:30 hrs)\nDÍA 2","DO"],"bg":["#ffffcc","#ffffcc","#ffffcc","#ffffcc","#ffffcc","#ffffcc","#ffffcc","#ffffcc","#ffffcc","#ffffcc","#ffffcc","#ffffcc","#999999","#999999","#ffff00","#f7caac","#ffffff","#ffffff","#999999","#38761d","#ff9900","#f7caac","#ffc000","#ffffff","#ffffff","#ffc000","#ffc000","#ffc000","#999999","#2f5496","#ffffff"],"fg":["#000000","#000000","#000000","#000000","#000000","#000000","#000000","#000000","#000000","#000000","#000000","#000000","#000000","#000000","#000000","#000000","#000000","#000000","#000000","#ffffff","#000000","#000000","#000000","#000000","#000000","#000000","#000000","#000000","#000000","#ffffff","#000000"]},{"bp":"2369624","nombre":"Patricia del Pilar Najar","dias":["VACACIONES","VACACIONES","VACACIONES","VACACIONES","VACACIONES","VACACIONES","Reentrenamiento A320F \nAlumna","DO","Habilitación B767 (CCM)\n- LIM-MIA\n- LA 2694 (13:30-19:30 hrs)","Habilitación B767 (CCM)\n- MIA-LIM\n- LA 2699 (23:10-05:00 hrs)","Blanco","REVA ANUAL INSTRUCTORES\n ALUMNO","DO","ENTREVISTAS","ACT\nRRVV","INICIAL G13 (CHEQUEO DGAC) \n- LIM-PIU-LIM \n- LA2125 - LA2126 (08:00 - 10:15 hrs)\n\n INICIAL G13 (CHEQUEO DGAC) \n- LIM-PIU-LIM \n-LA2308 - LA2309 (13:10 - 15:25 hrs)","DO","DO","Inicial G13 \nCHEQUEO LATAM\nLA2052 - LA2051 - LA2135 - LA2136\nLIM - TBP - LIM - TRU - LIM","RESERVA IET TARDE","Reentrenamiento A320F\nLIM-AQP-LIM\n2123/2124","DO","DO","DO","DO","Inicial G1\nVISITA GUIADA","Inicial G1\nVISITA GUIADA","Blanco Recojo","LCK B767\n- LIM-MIA\n- LA 2480 (00:15-06:15 hrs)","Habilitación B767*\n- MIA-LIM\n- LA 2481 (17:55-23:40 hrs)","Blanco"],"bg":["#ffffcc","#ffffcc","#ffffcc","#ffffcc","#ffffcc","#ffffcc","#f7caac","#ffffff","#ffc000","#ffc000","#ffc000","#ff9900","#ffffff","#999999","#ffff00","#38761d","#ffffff","#ffffff","#38761d","#d9d9d9","#f7caac","#ffffff","#ffffff","#ffffff","#ffffff","#fff2cc","#fff2cc","#ffc000","#ffc000","#ffc000","#ffc000"],"fg":["#000000","#000000","#000000","#000000","#000000","#000000","#000000","#000000","#000000","#000000","#000000","#000000","#000000","#000000","#000000","#ffffff","#000000","#000000","#ffffff","#000000","#000000","#000000","#000000","#000000","#000000","#000000","#000000","#000000","#000000","#000000","#000000"]},{"bp":"3134911","nombre":"Javier Zapata","dias":["DO","Inicial G13","DO","DO","REVA ANUAL INSTRUCTORES\n ALUMNO","LCK ALUMNO A320F (CCM)\nLIM-AQP-LIM\nLA 2123 (09:20-11:00 hrs)\nLA 2124 (11:35-13:10 hrs)\nHABILITACIÓN A320F (A320F)\nLIM-AQP-LIM\nLA 2115 (13:55-15:25 hrs)\nLA 2114 (16:00-17:35 hrs)","HO FILE","DO","DO","DO","DO","Inicial G1","LCK B767\n- LIM-MIA\n- LA 2698 (08:25-14:20 hrs)","Habilitación B767\n- MIA-LIM\n- LA 2699 (23:10-05:00 hrs)","Blanco","Inicial G2","DO","DO","HO FILE","Inicial G2","Inicial G2","RTI: PRÁCTICA\nA320F / B767\n(08:30-17:30 hrs)\nINS APOYO TM","Inicial G13\nCHEQUEO DGAC\nLA2274 - LA2275\t\nLIM - CIX - LIM","DO","DO","Inicial G1","HO FILE","HO FILE","LCK B767\n- LIM-BOG\n- LA 2489 (13:00-16:15 hrs)\nLCK B767\n- BOG-LIM\n- LA 2488 (17:20-20:45 hrs)","Reentrenamiento A320F + Recalificación A320F\nLIM-PCL-LIM\n2360/2361","DO"],"bg":["#ffffff","#38761d","#ffffff","#ffffff","#ff9900","#f7caac","#999999","#ffffff","#ffffff","#ffffff","#ffffff","#fff2cc","#ffc000","#ffc000","#ffc000","#b4a7d6","#ffffff","#ffffff","#999999","#b4a7d6","#b4a7d6","#cce0f4","#38761d","#ffffff","#ffffff","#fff2cc","#999999","#999999","#ffc000","#f7caac","#ffffff"],"fg":["#000000","#ffffff","#000000","#000000","#000000","#000000","#000000","#000000","#000000","#000000","#000000","#000000","#000000","#000000","#000000","#ffffff","#000000","#000000","#000000","#ffffff","#ffffff","#000000","#ffffff","#000000","#000000","#000000","#000000","#000000","#000000","#000000","#000000"]},{"bp":"3750335","nombre":"Jefferson Mendez","dias":["DO","HO FILE","DO","DO","LCK A320F\r\nLIM-AQP-LIM\r\nLA 2123 (09:20-11:00 hrs)\r\nLA 2124 (11:35-13:10 hrs)\r\nLCK A320F\r\nLIM-TPP-LIM\r\nLA 2087 (14:10-15:35 hrs)\r\nLA 2088 (16:10-17:30 hrs)","REVA ANUAL INSTRUCTORES\nINSTRUCTOR","LCK A320F\r\nLIM-AQP-LIM\r\nLA 2123 (09:20-11:00 hrs)\r\nLA 2124 (11:35-13:10 hrs)\r\nLCK A320F\r\nLIM-PCL-LIM\r\nLA 2360 (14:05-15:20 hrs)\r\nLA 2361 (15:55-17:10 hrs)","DO","DO","DO","DO","LCK A320F\r\nLIM-TCQ-LIM\r\nLA 2245 (09:00-10:50 hrs)\r\nLA 2244 (11:25-13:15 hrs)\r\nLCK A320F\r\nLIM-TPP-LIM\r\nLA 2087 (14:10-15:35 hrs)\r\nLA 2088 (16:10-17:30 hrs)","Inicial G2","Blanco Recojo","LCK B767\n- LIM-MIA\n- LA 2480 (00:15-06:15 hrs)","Habilitación B767\n- MIA-LIM\n- LA 2481 (15:55-21:40 hrs)","DO","DO","TALLER VOLUNTARIO SEG","Reentrenamiento A320F\r\nLIM-AQP-LIM\r\nLA 2123 (09:20-11:00 hrs)\r\nLA 2124 (11:35-13:10 hrs)\r\nLCK A320F\r\nLIM-PCL-LIM\r\nLA 2360 (14:05-15:20 hrs)\r\nLA 2361 (15:55-17:10 hrs)","Inicial G1","Inicial G1\nVISITA GUIADA","Inicial G1\nVISITA GUIADA","DO","DO","LCK A320F\r\nLIM-AQP-LIM\r\nLA 2123 (09:20-11:00 hrs)\r\nLA 2124 (11:35-13:10 hrs)\r\nLCK A320F\r\nLIM-TPP-LIM\r\nLA 2087 (14:10-15:35 hrs)\r\nLA 2088 (16:10-17:30 hrs)","HO FILE","Reva de Servicio\n(08:30-17:30 hrs)\nDÍA 2","RTI: PRÁCTICA\nA320F / B767\n(08:30-17:30 hrs)\nINS TITULAR","LCK B767\n- LIM-BOG\n- LA 2489 (13:00-16:15 hrs)\nLCK B767\n- BOG-LIM\n- LA 2488 (17:20-20:45 hrs)","DO"],"bg":["#ffffff","#999999","#ffffff","#ffffff","#f7caac","#ff9900","#f7caac","#ffffff","#ffffff","#ffffff","#ffffff","#f7caac","#b4a7d6","#ffc000","#ffc000","#ffc000","#ffffff","#ffffff","#ffff00","#f7caac","#fff2cc","#fff2cc","#fff2cc","#ffffff","#ffffff","#f7caac","#999999","#2f5496","#cce0f4","#ffc000","#ffffff"],"fg":["#000000","#000000","#000000","#000000","#000000","#000000","#000000","#000000","#000000","#000000","#000000","#000000","#ffffff","#000000","#000000","#000000","#000000","#000000","#000000","#000000","#000000","#000000","#000000","#000000","#000000","#000000","#000000","#ffffff","#000000","#000000","#000000"]},{"bp":"3852423","nombre":"Gabriela Ungaro","dias":["DO","Inicial G13","DO","DO","REVA ANUAL INSTRUCTORES\n INSTRUCTOR","LCK A320F\r\nLIM-TCQ-LIM\r\nLA 2245 (09:00-10:50 hrs)\r\nLA 2244 (11:25-13:15 hrs)\r\nLCK A320F\r\nLIM-TPP-LIM\r\nLA 2087 (14:10-15:35 hrs)\r\nLA 2088 (16:10-17:30 hrs)","Reva de Servicio\n(08:30-17:30 hrs)\nDÍA 2","DO","DO","DO","DO","LCK A320F\nLIM-AQP-LIM\nLA 2123 (09:20-11:00 hrs)\nLA 2124 (11:35-13:10 hrs)\nLCK A320F\nLIM-CUZ-LIM\nLA 2075 (14:25-15:50 hrs)\nLA 2076 (16:25-18:00 hrs)","Inicial G13\nCHEQUEO LATAM\nLA2227 - LA2228 - LA2276 \nLIM - TRU - LIM - CUZ - LIM","DO","ACT\nRRVV","CHEQUEO DGAC A320F (50%)\nLIM-PIU-LIM\nLA 2306 (09:35-11:20 hrs)\nLA 2307 (11:55-13:25 hrs)","DO","DO","TALLER VOLUNTARIO SEG","Inicial G1","Inicial G13 \nCHEQUEO DGAC\nLA2238 - LA2239 \nLIM - CUZ - LIM","LCK A320F\nLIM-AQP-LIM\nLA 2123 (09:20-11:00 hrs)\nLA 2124 (11:35-13:10 hrs)\nLCK A320F\nLIM-TPP-LIM\nLA 2087 (14:10-15:35 hrs)\nLA 2088 (16:10-17:30 hrs)","Inicial G2","DO","DO","Recalificación A320F + Habilitación A320F\nLIM-CUZ-LIM\nLA 2238 (10:15-11:40 hrs)\nLA 2239 (12:15-13:45 hrs)","DESCANSO MÉDICO","DESCANSO MÉDICO","Inicial G1","LCK A320F\r\nLIM-PIU-LIM\r\nLA 2306 (09:35-11:20 hrs)\r\nLA 2307 (11:55-13:25 hrs)\r\nLCK A320F\r\nLIM-CIX-LIM\r\nLA 2312 (14:25-15:55 hrs)\r\nLA 2313 (16:35-18:00 hrs)","DO"],"bg":["#ffffff","#38761d","#ffffff","#ffffff","#ff9900","#f7caac","#2f5496","#ffffff","#ffffff","#ffffff","#ffffff","#f7caac","#38761d","#ffffff","#ffff00","#f7caac","#ffffff","#ffffff","#ffff00","#fff2cc","#38761d","#f7caac","#b4a7d6","#ffffff","#ffffff","#f7caac","#fce5cd","#fce5cd","#fff2cc","#f7caac","#ffffff"],"fg":["#000000","#ffffff","#000000","#000000","#000000","#000000","#ffffff","#000000","#000000","#000000","#000000","#000000","#ffffff","#000000","#000000","#000000","#000000","#000000","#000000","#000000","#ffffff","#000000","#ffffff","#000000","#000000","#000000","#000000","#000000","#000000","#000000","#000000"]},{"bp":"2604360","nombre":"Mariella Carrasco","dias":["DO","DO","DO","DO","Inicial G13","Reva de Servicio\n(08:30-17:30 hrs)\nDÍA 1","Reentrenamiento A320F + Habilitación A320F","HO FILE","Inicial G2","DO","DO","LCK A320F\r\nLIM-CIX-LIM\r\nLA 2274 (09:40-11:10 hrs)\r\nLA 2275 (11:45-13:05 hrs)\r\nLCK A320F\r\nLIM-AQP-LIM\r\nLA 2115 (13:55-15:25 hrs)\r\nLA 2114 (16:00-17:35 hrs)","HO FILE","Inicial G2","Inicial G13\nCHEQUEO LATAM\nLA2184 - LA2183 \nLIM - AYP - LIM","HO FILE","DO","DO","HO FILE","HO FILE","Inicial G13 \nCHEQUEO DGAC\nLA2260- LA2261 \nLIM - PEM- LIM","Inicial G13 \nCHEQUEO DGAC\nLA2081 - LA2082 \nLIM - TPP - LIM","Chequeo DGAC B767\n- LIM-BOG\n- LA 2489 (13:00-16:15 hrs)\nLCK ALUMNA B767 (CST)\n- BOG-LIM\n- LA 2488 (17:20-20:45 hrs)","DO","DO","HO FILE","LCK B767\n- LIM-MIA\n- LA 2698 (08:25-14:20 hrs)","Reentrenamiento B767\n- MIA-LIM\n- LA 2699 (23:10-05:00 hrs)","Blanco","LCK A320F\r\nLIM-AQP-LIM\r\nLA 2123 (09:20-11:00 hrs)\r\nLA 2124 (11:35-13:10 hrs)\r\nLCK A320F\r\nLIM-TPP-LIM\r\nLA 2087 (14:10-15:35 hrs)\r\nLA 2088 (16:10-17:30 hrs)","DO"],"bg":["#ffffff","#ffffff","#ffffff","#ffffff","#38761d","#2f5496","#f7caac","#999999","#b4a7d6","#ffffff","#ffffff","#f7caac","#999999","#b4a7d6","#38761d","#999999","#ffffff","#ffffff","#999999","#999999","#38761d","#38761d","#ffc000","#ffffff","#ffffff","#999999","#ffc000","#ffc000","#ffc000","#f7caac","#ffffff"],"fg":["#000000","#000000","#000000","#000000","#ffffff","#ffffff","#000000","#000000","#ffffff","#000000","#000000","#000000","#000000","#ffffff","#ffffff","#000000","#000000","#000000","#000000","#000000","#ffffff","#ffffff","#000000","#000000","#000000","#000000","#000000","#000000","#000000","#000000","#000000"]},{"bp":"2823133","nombre":"Cesar Campos","dias":["DO","CAPACITACION RRVV","DO","DO","Reentrenamiento B767\n- LIM-MIA\n- LA 2694 (13:30-19:30 hrs)","Habilitación B767*\n- MIA-LIM\n- LA 2699 (23:10-05:00 hrs)","Blanco","DO","DO","DO","DO","REVA ANUAL INSTRUCTORES\n ALUMNO","Inicial G13\nCHEQUEO LATAM\nLA2130 - LA2129 - LA2308 - LA2309\nLIM - CUZ - LIM - PIU - LIM","HO FILE","ACT\nRRVV","Reva de Servicio\n(08:30-17:30 hrs)\nDÍA 2","DO","DO","Inicial G13 \nCHEQUEO LATAM\nLA2130 - LA2129 - LA2308 - LA2309 \nLIM - CUZ - LIM - PIU - LIM","RTI: VIRTUAL\nA320F / B767\n(08:30-17:30 hrs)\nINS TITULAR","Inicial G13\nCHEQUEO LATAM\nLA2013 - LA2014 - LA2356 - LA2532\nLIM - CUZ - LIM - CUZ - LIM","RTI: PRÁCTICA\nA320F / B767\n(08:30-17:30 hrs)\nINS TITULAR","HO FILE","DO","DO","HANDS ON B767","HO FILE","Inicial G1","HO FILE","Inicial G2","DO"],"bg":["#ffffff","#d0e0e3","#ffffff","#ffffff","#ffc000","#ffc000","#ffc000","#ffffff","#ffffff","#ffffff","#ffffff","#ff9900","#38761d","#999999","#ffff00","#2f5496","#ffffff","#ffffff","#38761d","#cce0f4","#38761d","#cce0f4","#999999","#ffffff","#ffffff","#ffff00","#999999","#fff2cc","#999999","#b4a7d6","#ffffff"],"fg":["#000000","#000000","#000000","#000000","#000000","#000000","#000000","#000000","#000000","#000000","#000000","#000000","#ffffff","#000000","#000000","#ffffff","#000000","#000000","#ffffff","#000000","#ffffff","#000000","#000000","#000000","#000000","#000000","#000000","#000000","#000000","#ffffff","#000000"]},{"bp":"3189967","nombre":"Kevin Segovia","dias":["DO","HO FILE","DO","DO","HABILITACIÓN A320F (A320F)\nLIM-CJA-LIM\nLA 2291 (05:10-06:30 hrs)\nLA 2290 (07:10-08:10 hrs)\nLCK ALUMNO A320F (CCM)\nLIM-AQP-LIM\nLA 2123 (09:20-11:00 hrs)\nLA 2124 (11:35-13:10 hrs)","REVA ANUAL INSTRUCTORES\n ALUMNO","RTI: VIRTUAL\nA320F / B767\n(08:30-17:30 hrs)\nINS CRM","DO","DO","DO","DO","CURSO 50%","CHEQUEO LATAM A320F (50%)\nLIM-TCQ-LIM\nLA 2245 (09:00-10:50 hrs)\nLA 2244 (11:25-13:15 hrs)","Inicial G1","Inicial G2","ENTREVISTAS","DO","DO","Inicial G13\nCHEQUEO LATAM\nLA2125 - LA2126 - LA2312 - LA2313 \nLIM - PIU - LIM - CIX - LIM","Inicial G13 \n(Recuperatorio)","Habilitación B767 (CCM)\n- LIM-ATL\n- LA 2482 (12:15-19:35 hrs)","Habilitación B767 (CCM)\n- ATL-LIM\n- LA 2483 (22:15-05:00 hrs)","Blanco","DO","DO","CURSO 50%","Inicial G2 (VISITA GUIADA)","Inicial G2 (VISITA GUIADA)","Inicial G2 (VISITA GUIADA)","HO FILE","DO"],"bg":["#ffffff","#999999","#ffffff","#ffffff","#f7caac","#ff9900","#cce0f4","#ffffff","#ffffff","#ffffff","#ffffff","#ffe599","#f7caac","#fff2cc","#b4a7d6","#999999","#ffffff","#ffffff","#38761d","#38761d","#ffc000","#ffc000","#ffc000","#ffffff","#ffffff","#ffe599","#b4a7d6","#b4a7d6","#b4a7d6","#999999","#ffffff"],"fg":["#000000","#000000","#000000","#000000","#000000","#000000","#000000","#000000","#000000","#000000","#000000","#000000","#000000","#000000","#ffffff","#000000","#000000","#000000","#ffffff","#ffffff","#000000","#000000","#000000","#000000","#000000","#000000","#ffffff","#ffffff","#ffffff","#000000","#000000"]},{"bp":"2415373","nombre":"Milagros Salas","dias":["DO","HO FILE","DO","DO","Inicial G1","REVA ANUAL INSTRUCTORES\n ALUMNO","Inicial G2","DO","DO","DO","DO","Inicial G2","Reva de Servicio\n(08:30-17:30 hrs)\nDÍA 1","Inicial G1","DESCANSO MÉDICO","DESCANSO MÉDICO","DO","DO","Inicial G2","Inicial G13\nCHEQUEO LATAM\nLA2147 - LA2148 - LA2087 - LA2088\nLIM - JUL - LIM - TPP - LIM","REVA ANUAL INSTRUCTORES INSTRUCTOR","Reva de Servicio\n(08:30-17:30 hrs)\nDÍA 1","Reva de Servicio\n(08:30-17:30 hrs)\nDÍA 2","DO","DO","Habilitación B767 (CCM)\n- LIM-ATL\n- LA 2482 (12:15-19:35 hrs)","Habilitación B767 (CCM)\n- ATL-LIM\n- LA 2483 (22:15-05:00 hrs)","Blanco","RTI: PRÁCTICA\nA320F / B767\n(08:30-17:30 hrs)\nINS APOYO","Inicial G13\nTALLER DÍA 2","DO"],"bg":["#ffffff","#999999","#ffffff","#ffffff","#fff2cc","#ff9900","#b4a7d6","#ffffff","#ffffff","#ffffff","#ffffff","#b4a7d6","#2f5496","#fff2cc","#fce5cd","#fce5cd","#ffffff","#ffffff","#b4a7d6","#38761d","#ff9900","#2f5496","#2f5496","#ffffff","#ffffff","#ffc000","#ffc000","#ffc000","#cce0f4","#38761d","#ffffff"],"fg":["#000000","#000000","#000000","#000000","#000000","#000000","#ffffff","#000000","#000000","#000000","#000000","#ffffff","#ffffff","#000000","#000000","#000000","#000000","#000000","#ffffff","#ffffff","#000000","#ffffff","#ffffff","#000000","#000000","#000000","#000000","#000000","#000000","#ffffff","#000000"]},{"bp":"2440915","nombre":"Judith Fernandez","dias":["VACACIONES","VACACIONES","VACACIONES","VACACIONES","VACACIONES","VACACIONES","VACACIONES","DO","DO","DO","DO","REVA ANUAL INSTRUCTORES\n ALUMNO","CURSO 50%","HO FILE","Chequeo LATAM B767\n- LIM-BOG\n- LA 2489 (13:00-16:15 hrs)\nHabilitación B767*\n- BOG-LIM\n- LA 2488 (17:20-20:45 hrs)","HO FILE TARDE","DO","DO","Inicial G13\nCHEQUEO LATAM\nLA2147 - LA2148 - LA2087 - LA2088\t\nLIM - JUL - LIM - TPP - LIM","RTI: VIRTUAL\nA320F / B767\n(08:30-17:30 hrs)\nINS CRM","CURSO 50%","RTI: PRÁCTICA\nA320F / B767\n(08:30-17:30 hrs)\nINS APOYO","CURSO 50%","DO","DO","HO FILE","RTI: VIRTUAL\nA320F / B767\n(08:30-17:30 hrs)\nINS CRM","Inicial G1","RTI: PRÁCTICA\nA320F / B767\n(08:30-17:30 hrs)\nINS TITULAR","DO","DO"],"bg":["#ffffcc","#ffffcc","#ffffcc","#ffffcc","#ffffcc","#ffffcc","#ffffcc","#ffffff","#ffffff","#ffffff","#ffffff","#ff9900","#ffe599","#999999","#ffc000","#999999","#ffffff","#ffffff","#38761d","#cce0f4","#ffe599","#cce0f4","#ffe599","#ffffff","#ffffff","#999999","#cce0f4","#fff2cc","#cce0f4","#ffffff","#ffffff"],"fg":["#000000","#000000","#000000","#000000","#000000","#000000","#000000","#000000","#000000","#000000","#000000","#000000","#000000","#000000","#000000","#000000","#000000","#000000","#ffffff","#000000","#000000","#000000","#000000","#000000","#000000","#000000","#000000","#000000","#000000","#000000","#000000"]},{"bp":"3796947","nombre":"Rafael Nieto","dias":["SICK","SICK","SICK","SICK","SICK","CUMP","CUMP","SICK","SICK","SICK","SICK","SICK","SICK","SICK","SICK","SICK","SICK","SICK","SICK","SICK","SICK","SICK","SICK","SICK","SICK","SICK","SICK","SICK","SICK","SICK","SICK"],"bg":["#ffffff","#ffffff","#ffffff","#ffffff","#ffffff","#ffc0cb","#ffc0cb","#ffffff","#ffffff","#ffffff","#ffffff","#ffffff","#ffffff","#ffffff","#ffffff","#ffffff","#ffffff","#ffffff","#ffffff","#ffffff","#ffffff","#ffffff","#ffffff","#ffffff","#ffffff","#ffffff","#ffffff","#ffffff","#ffffff","#ffffff","#ffffff"],"fg":["#000000","#000000","#000000","#000000","#000000","#000000","#000000","#000000","#000000","#000000","#000000","#000000","#000000","#000000","#000000","#000000","#000000","#000000","#000000","#000000","#000000","#000000","#000000","#000000","#000000","#000000","#000000","#000000","#000000","#000000","#000000"]},{"bp":"3841387","nombre":"Gianfranco Celiz","dias":["DO","CURSO 50%","DO","DO","REVA ANUAL INSTRUCTORES\n ALUMNO","Inicial G13","RTI: VIRTUAL\nA320F / B767\n(08:30-17:30 hrs)\nINS TITULAR","DO","DO","DO","DO","TALLER VOLUNTARIO SEG","RTI: VIRTUAL\nA320F / B767 / B787\n(08:30-17:30 hrs)\nINS CRM","HO FILE","DO","VACACIONES","VACACIONES","VACACIONES","VACACIONES","VACACIONES","VACACIONES","VACACIONES","VACACIONES","DO","DO","Inicial G2","RTI: VIRTUAL\nA320F / B767\n(08:30-17:30 hrs)\nINS TITULAR","HO FILE","Reva de Servicio\n(08:30-17:30 hrs)\nDÍA 1","Inicial G1","DO"],"bg":["#ffffff","#ffe599","#ffffff","#ffffff","#ff9900","#38761d","#cce0f4","#ffffff","#ffffff","#ffffff","#ffffff","#ffff00","#cce0f4","#999999","#ffffff","#ffffcc","#ffffcc","#ffffcc","#ffffcc","#ffffcc","#ffffcc","#ffffcc","#ffffcc","#ffffff","#ffffff","#b4a7d6","#cce0f4","#999999","#2f5496","#fff2cc","#ffffff"],"fg":["#000000","#000000","#000000","#000000","#000000","#ffffff","#000000","#000000","#000000","#000000","#000000","#000000","#000000","#000000","#000000","#000000","#000000","#000000","#000000","#000000","#000000","#000000","#000000","#000000","#000000","#ffffff","#000000","#000000","#ffffff","#000000","#000000"]}]} | C2: 46318.36 | D2: Google Sheet
